
# Created by Ruins mod version 14.4 Ingame Parser
# authoring Player: Drock1994

weight=1
embed_into_distance=0
acceptable_target_blocks=
unacceptable_target_blocks=flowing_water,water,flowing_lava,lava
dimensions=32,14,17
allowable_overhang=0
max_leveling=2
leveling_buffer=0
preserve_water=0
preserve_lava=0

rule1=0,100,minecraft:stone-0
rule2=0,100,minecraft:stonebrick-0
rule3=0,100,chisel:marble-0
rule4=0,100,minecraft:glowstone-0
rule5=0,100,minecraft:log-2
rule6=0,100,minecraft:birch_stairs-2
rule7=0,100,minecraft:planks-2
rule8=0,100,minecraft:crafting_table-0
rule9=0,100,minecraft:carpet-15
rule10=0,100,minecraft:wooden_door-1
rule11=0,100,minecraft:wooden_door-3
rule12=0,100,ForgeMultipart:block-0
rule13=0,100,minecraft:furnace-4
rule14=0,100,chisel:stained_glass_yellow-12
rule15=0,100,minecraft:birch_stairs-5
rule16=0,100,minecraft:wooden_door-9
rule17=0,100,minecraft:wooden_door-8
rule18=0,100,minecraft:birch_stairs-0
rule19=0,100,minecraft:log-6
rule20=0,100,chisel:glass-4
rule21=0,100,minecraft:iron_bars-0
rule22=0,100,chisel:glass-7
rule23=0,100,minecraft:wooden_door-0
rule24=0,100,ChestGenHook:dungeonChest:5-3
rule25=0,100,ChestGenHook:dungeonChest:5-2
rule26=0,100,minecraft:wooden_door-2
rule27=2,100,minecraft:torch-1
rule28=2,100,minecraft:torch-3
rule29=2,100,minecraft:torch-4
rule30=2,100,minecraft:torch-2
rule31=0,100,minecraft:wool-15
rule32=0,100,minecraft:snow_layer-0
rule33=0,100,minecraft:wool-0
rule34=0,100,minecraft:log-10
rule35=0,100,minecraft:birch_stairs-1
rule36=0,100,minecraft:birch_stairs-3
rule37=0,100,minecraft:fence-0

layer
1,1,1,1,1,1,1,1,1,1,1,1,1,1,1,1,1
1,1,1,1,1,2,2,2,2,2,2,1,1,1,1,1,1
1,1,1,1,2,3,3,3,3,3,3,3,2,1,1,1,1
1,1,1,2,3,3,3,3,3,3,3,3,3,2,1,1,1
1,1,2,3,3,3,3,3,3,3,3,3,3,3,2,1,1
1,2,3,3,3,3,3,3,3,3,3,3,3,3,3,1,1
1,3,3,3,3,3,3,3,4,3,3,3,3,3,3,3,1
1,3,3,3,3,3,3,3,4,3,3,3,3,3,3,3,1
1,2,3,3,3,3,3,3,3,3,3,3,3,3,3,1,1
1,1,2,3,3,3,3,3,3,3,3,3,3,3,2,1,1
1,1,1,2,3,3,3,3,3,3,3,3,3,2,1,1,1
1,1,1,1,2,3,3,3,3,3,3,3,2,1,1,1,1
1,1,1,1,1,2,2,2,2,2,2,2,1,1,1,1,1
1,1,1,1,1,1,1,1,1,1,1,1,1,1,1,1,1
endlayer

layer
0,0,0,0,0,0,0,0,0,0,0,0,0,0,0,0,0
0,0,0,0,0,5,2,2,2,2,2,5,0,0,0,0,0
0,0,0,0,2,7,7,6,0,0,0,0,2,0,0,0,0
0,0,0,2,0,0,8,0,0,0,0,0,0,2,0,0,0
0,0,2,0,0,0,0,0,0,0,0,0,0,0,2,0,0
0,5,0,0,0,0,0,9,9,9,0,0,0,0,0,5,0
0,11,0,0,0,0,0,9,9,9,0,0,0,0,0,10,0
0,11,0,0,0,0,0,9,9,9,0,0,0,0,0,10,0
0,5,0,0,0,0,0,9,9,9,0,0,0,0,0,5,0
0,0,2,0,0,0,0,0,0,0,0,0,0,0,2,0,0
0,0,0,2,0,0,0,0,0,0,0,0,0,2,0,0,0
0,0,0,0,2,0,0,12,13,12,0,0,2,0,0,0,0
0,0,0,0,0,5,2,2,2,2,2,5,0,0,0,0,0
0,0,0,0,0,0,0,0,0,0,0,0,0,0,0,0,0
endlayer

layer
0,0,0,0,0,0,0,0,0,0,0,0,0,0,0,0,0
0,0,0,0,0,5,2,14,14,14,2,5,0,0,0,0,0
0,0,0,0,2,7,6,0,0,0,0,0,2,0,0,0,0
0,0,0,2,0,15,0,0,0,0,0,0,0,2,0,0,0
0,0,2,0,0,0,0,0,0,0,0,0,0,0,2,0,0
0,5,0,0,0,0,0,0,0,0,0,0,0,0,0,5,0
0,17,0,0,0,0,0,0,0,0,0,0,0,0,0,16,0
0,16,0,0,0,0,0,0,0,0,0,0,0,0,0,17,0
0,5,0,0,0,0,0,0,0,0,0,0,0,0,0,5,0
0,0,2,0,0,0,0,0,0,0,0,0,0,0,2,0,0
0,0,0,2,0,0,0,0,0,0,0,0,0,2,0,0,0
0,0,0,0,2,0,0,0,0,0,0,0,2,0,0,0,0
0,0,0,0,0,5,2,14,14,14,2,5,0,0,0,0,0
0,0,0,0,0,0,0,0,0,0,0,0,0,0,0,0,0
endlayer

layer
0,0,0,0,0,0,0,0,0,0,0,0,0,0,0,0,0
0,0,0,0,0,5,2,14,14,14,2,5,0,0,0,0,0
0,0,0,0,2,0,0,0,0,0,0,0,2,0,0,0,0
0,0,0,2,0,18,0,0,0,0,0,0,0,2,0,0,0
0,0,2,0,0,15,0,0,0,0,0,0,0,0,2,0,0
0,5,0,0,0,0,0,0,0,0,0,0,0,0,0,5,0
0,19,0,0,0,0,0,0,0,0,0,0,0,0,0,19,0
0,19,0,0,0,0,0,0,0,0,0,0,0,0,0,19,0
0,5,0,0,0,0,0,0,0,0,0,0,0,0,0,5,0
0,0,2,0,0,0,0,0,0,0,0,0,0,0,2,0,0
0,0,0,2,0,0,0,0,0,0,0,0,0,2,0,0,0
0,0,0,0,2,0,0,0,0,0,0,0,2,0,0,0,0
0,0,0,0,0,5,2,14,14,14,2,5,0,0,0,0,0
0,0,0,0,0,0,0,0,0,0,0,0,0,0,0,0,0
endlayer

layer
0,0,0,0,0,0,0,0,0,0,0,0,0,0,0,0,0
0,0,0,0,0,5,2,14,14,14,2,5,0,0,0,0,0
0,0,0,0,2,0,0,0,0,0,0,0,2,0,0,0,0
0,0,0,2,0,0,0,0,0,0,0,0,0,2,0,0,0
0,0,2,0,0,18,0,0,0,0,0,0,0,0,2,0,0
0,5,0,0,0,15,0,0,0,0,0,0,0,0,0,5,0
0,20,0,0,0,0,0,0,0,0,0,0,0,0,0,20,0
0,20,0,0,0,0,0,0,0,0,0,0,0,0,0,20,0
0,5,0,0,0,0,0,0,0,0,0,0,0,0,0,5,0
0,0,2,0,0,0,0,0,0,0,0,0,0,0,2,0,0
0,0,0,2,0,0,0,0,0,0,0,0,0,2,0,0,0
0,0,0,0,2,0,0,0,0,0,0,0,2,0,0,0,0
0,0,0,0,0,5,2,14,14,14,2,5,0,0,0,0,0
0,0,0,0,0,0,0,0,0,0,0,0,0,0,0,0,0
endlayer

layer
0,0,0,0,0,0,0,0,0,0,0,0,0,0,0,0,0
0,0,0,0,0,20,20,20,20,20,20,20,0,0,0,0,0
0,0,0,12,20,0,0,0,12,0,0,0,20,12,0,0,0
0,0,12,20,0,0,0,0,0,0,0,0,0,20,12,0,0
0,0,20,12,0,0,0,0,0,0,0,0,0,0,20,0,0
0,20,0,0,0,18,0,0,0,0,0,12,0,0,0,20,0
0,20,0,0,0,7,0,0,0,0,0,0,0,0,0,20,0
0,20,0,0,0,0,0,0,0,12,0,0,0,0,0,20,0
0,20,0,0,0,12,0,0,0,0,0,12,0,0,0,20,0
0,0,20,12,0,0,0,0,0,0,0,0,0,12,20,0,0
0,0,12,20,12,0,0,0,0,0,0,0,12,20,12,0,0
0,0,0,12,20,0,0,0,0,0,0,0,20,12,0,0,0
0,0,0,0,0,20,20,20,20,20,20,20,0,0,0,0,0
0,0,0,0,0,0,0,0,0,0,0,0,0,0,0,0,0
endlayer

layer
0,0,0,7,7,7,7,7,7,7,7,7,7,7,0,0,0
0,0,7,7,7,7,7,7,7,7,7,7,7,7,7,0,0
0,7,7,7,7,7,7,7,7,7,7,7,7,7,7,7,0
7,7,7,7,7,0,7,7,7,7,7,7,7,7,7,7,7
7,7,7,7,7,0,7,7,7,7,7,7,7,7,7,7,7
7,7,7,7,7,0,7,7,7,7,7,7,7,7,7,7,7
7,7,7,7,7,18,7,7,7,7,7,7,7,7,7,7,7
7,7,7,7,7,7,7,7,7,7,7,7,7,7,7,7,7
7,7,7,7,7,7,7,7,7,7,7,7,7,7,7,7,7
7,7,7,7,7,7,7,7,7,7,7,7,7,7,7,7,7
7,7,7,7,7,7,7,7,7,7,7,7,7,7,7,7,7
0,7,7,7,7,7,7,7,7,7,7,7,7,7,7,7,0
0,0,7,7,7,7,7,7,7,7,7,7,7,7,7,0,0
0,0,0,7,7,7,7,7,7,7,7,7,7,7,0,0,0
endlayer

layer
0,0,0,21,21,21,21,21,21,21,21,21,21,21,0,0,0
0,0,21,21,0,0,0,0,0,0,0,0,0,21,21,0,0
0,21,21,0,0,5,2,22,23,22,2,5,0,0,21,21,0
21,21,0,0,2,0,0,0,0,0,0,0,2,0,0,21,21
21,0,0,2,0,0,0,0,0,0,0,0,0,2,0,0,21
21,0,5,0,0,0,0,0,0,0,0,0,0,0,5,0,21
21,0,2,25,0,0,0,0,0,0,0,0,0,24,2,0,21
21,0,2,25,0,0,0,0,0,0,0,0,0,24,2,0,21
21,0,5,0,0,0,0,0,0,0,0,0,0,0,5,0,21
21,0,0,2,0,0,0,0,0,0,0,0,0,2,0,0,21
21,21,0,0,2,0,0,0,0,0,0,0,2,0,0,21,21
0,21,21,0,0,5,2,22,26,22,2,5,0,0,21,21,0
0,0,21,21,0,0,0,0,0,0,0,0,0,21,21,0,0
0,0,0,21,21,21,21,21,21,21,21,21,21,21,0,0,0
endlayer

layer
0,0,0,0,0,0,0,0,0,0,0,0,0,0,0,0,0
0,0,0,0,0,0,0,0,0,0,0,0,0,0,0,0,0
0,0,0,0,0,5,2,22,16,22,2,5,0,0,0,0,0
0,0,0,0,2,0,0,0,0,0,0,0,2,0,0,0,0
0,0,0,2,0,0,0,0,0,0,0,0,0,2,0,0,0
0,0,5,0,0,0,0,0,0,0,0,0,0,0,5,0,0
0,0,2,0,0,0,0,0,0,0,0,0,0,0,2,0,0
0,0,2,0,0,0,0,0,0,0,0,0,0,0,2,0,0
0,0,5,0,0,0,0,0,0,0,0,0,0,0,5,0,0
0,0,0,2,0,0,0,0,0,0,0,0,0,2,0,0,0
0,0,0,0,2,0,0,0,0,0,0,0,2,0,0,0,0
0,0,0,0,0,5,2,22,16,22,2,5,0,0,0,0,0
0,0,0,0,0,0,0,0,0,0,0,0,0,0,0,0,0
0,0,0,0,0,0,0,0,0,0,0,0,0,0,0,0,0
endlayer

layer
0,0,0,0,0,0,0,0,0,0,0,0,0,0,0,0,0
0,0,0,0,0,0,0,0,0,0,0,0,0,0,0,0,0
0,0,0,0,0,5,2,2,2,2,2,5,0,0,0,0,0
0,0,0,0,2,0,0,0,0,0,0,0,2,0,0,0,0
0,0,0,2,12,0,0,0,0,0,0,0,12,2,0,0,0
0,0,5,0,0,0,0,0,0,0,0,0,0,0,5,0,0
0,0,2,0,0,0,0,0,0,0,0,0,0,0,2,0,0
0,0,2,0,0,0,0,0,0,0,0,0,0,0,2,0,0
0,0,5,0,0,0,0,0,0,0,0,0,0,0,5,0,0
0,0,0,2,12,0,0,0,0,0,0,0,12,2,0,0,0
0,0,0,0,2,0,0,0,0,0,0,0,2,0,0,0,0
0,0,0,0,0,5,2,2,2,2,2,5,0,0,0,0,0
0,0,0,0,0,0,0,0,0,0,0,0,0,0,0,0,0
0,0,0,0,0,0,0,0,0,0,0,0,0,0,0,0,0
endlayer

layer
0,0,0,0,0,0,0,0,0,0,0,0,0,0,0,0,0
0,0,0,0,0,0,0,0,0,0,0,0,0,0,0,0,0
0,0,0,0,0,5,2,2,2,2,2,5,0,0,0,0,0
0,0,0,0,2,0,0,0,27,0,0,0,2,0,0,0,0
0,0,0,2,29,0,0,0,0,0,0,0,28,2,0,0,0
0,0,5,20,0,0,0,0,0,0,0,0,0,20,5,0,0
0,0,2,20,0,0,0,0,0,0,0,0,0,20,2,0,0
0,0,2,20,0,0,0,0,0,0,0,0,0,20,2,0,0
0,0,5,20,0,0,0,0,0,0,0,0,0,20,5,0,0
0,0,0,2,29,0,0,0,0,0,0,0,28,2,0,0,0
0,0,0,0,2,0,0,0,30,0,0,0,2,0,0,0,0
0,0,0,0,0,5,2,2,2,2,2,5,0,0,0,0,0
0,0,0,0,0,0,0,0,0,0,0,0,0,0,0,0,0
0,0,0,0,0,0,0,0,0,0,0,0,0,0,0,0,0
endlayer

layer
0,0,0,0,0,0,0,0,0,0,0,0,0,0,0,0,0
0,0,0,0,0,0,0,0,0,0,0,0,0,0,0,0,0
0,0,0,0,0,21,0,0,0,0,0,21,0,0,0,0,0
0,0,0,0,21,5,2,2,14,2,2,5,21,0,0,0,0
0,0,0,21,7,0,0,0,0,0,0,0,7,21,0,0,0
0,0,21,5,0,0,0,0,0,0,0,0,0,5,21,0,0
0,0,0,2,0,0,0,0,0,0,0,0,0,2,21,0,0
0,0,0,2,0,0,0,0,0,0,0,0,0,2,21,0,0
0,0,21,5,0,0,0,0,0,0,0,0,0,5,21,0,0
0,0,0,21,7,0,0,0,0,0,0,0,7,21,0,0,0
0,0,0,0,21,5,2,2,14,2,2,5,21,0,0,0,0
0,0,0,0,0,21,0,0,0,0,0,21,0,0,0,0,0
0,0,0,0,0,0,0,0,0,0,0,0,0,0,0,0,0
0,0,0,0,0,0,0,0,0,0,0,0,0,0,0,0,0
endlayer

layer
0,0,0,0,0,0,0,0,0,0,0,0,0,0,0,0,0
0,0,0,0,0,0,0,0,0,0,0,0,0,0,0,0,0
0,0,0,0,0,0,0,0,0,0,0,0,0,0,0,0,0
0,0,0,0,0,5,2,14,14,14,2,5,0,0,0,0,0
0,0,0,0,7,0,0,0,0,0,0,0,7,0,0,0,0
0,0,0,5,0,0,0,0,0,0,0,0,0,5,0,0,0
0,0,0,2,0,0,0,0,0,0,0,0,0,2,0,0,0
0,0,0,2,0,0,0,0,0,0,0,0,0,2,0,0,0
0,0,0,5,0,0,0,0,0,0,0,0,0,5,0,0,0
0,0,0,0,7,0,0,0,0,0,0,0,7,0,0,0,0
0,0,0,0,0,5,2,14,14,14,2,5,0,0,0,0,0
0,0,0,0,0,0,0,0,0,0,0,0,0,0,0,0,0
0,0,0,0,0,0,0,0,0,0,0,0,0,0,0,0,0
0,0,0,0,0,0,0,0,0,0,0,0,0,0,0,0,0
endlayer

layer
0,0,0,0,0,0,0,0,0,0,0,0,0,0,0,0,0
0,0,0,0,0,0,0,0,0,0,0,0,0,0,0,0,0
0,0,0,0,0,0,0,0,0,0,0,0,0,0,0,0,0
0,0,0,0,0,5,2,2,14,2,2,5,0,0,0,0,0
0,0,0,0,7,0,0,0,0,0,0,0,7,0,0,0,0
0,0,0,5,0,0,0,0,0,0,0,0,0,5,0,0,0
0,0,0,2,0,0,0,0,0,0,0,0,0,2,0,0,0
0,0,0,2,0,0,0,0,0,0,0,0,0,2,0,0,0
0,0,0,5,0,0,0,0,0,0,0,0,0,5,0,0,0
0,0,0,0,7,0,0,0,0,0,0,0,7,0,0,0,0
0,0,0,0,0,5,2,2,14,2,2,5,0,0,0,0,0
0,0,0,0,0,0,0,0,0,0,0,0,0,0,0,0,0
0,0,0,0,0,0,0,0,0,0,0,0,0,0,0,0,0
0,0,0,0,0,0,0,0,0,0,0,0,0,0,0,0,0
endlayer

layer
0,0,0,0,0,0,0,0,0,0,0,0,0,0,0,0,0
0,0,0,0,0,0,0,0,0,0,0,0,0,0,0,0,0
0,0,0,0,0,0,0,0,0,0,0,0,0,0,0,0,0
0,0,0,0,0,5,2,2,2,2,2,5,0,0,0,0,0
0,0,0,0,7,7,0,0,0,0,0,7,7,0,0,0,0
0,0,0,5,7,0,0,0,0,0,0,0,7,5,0,0,0
0,0,0,2,0,0,0,0,0,0,0,0,0,2,0,0,0
0,0,0,2,0,0,0,0,0,0,0,0,0,2,0,0,0
0,0,0,5,7,0,0,0,0,0,0,0,7,5,0,0,0
0,0,0,0,7,7,0,0,0,0,0,7,7,0,0,0,0
0,0,0,0,0,5,2,2,2,2,2,5,0,0,0,0,0
0,0,0,0,0,0,0,0,0,0,0,0,0,0,0,0,0
0,0,0,0,0,0,0,0,0,0,0,0,0,0,0,0,0
0,0,0,0,0,0,0,0,0,0,0,0,0,0,0,0,0
endlayer

layer
0,0,0,31,0,0,0,0,0,0,0,0,0,0,0,0,0
0,0,0,0,0,0,0,0,0,0,0,0,0,0,0,0,0
0,0,0,0,0,0,0,0,0,0,0,0,0,0,0,0,0
0,0,0,0,0,21,21,21,21,21,21,21,0,0,0,0,0
0,0,0,0,21,21,2,2,2,2,2,21,21,0,0,0,0
0,0,0,0,32,7,0,0,0,0,0,7,21,21,0,0,0
0,0,0,0,2,0,0,0,0,0,0,0,2,21,0,0,0
0,0,0,0,2,0,0,0,0,0,0,0,2,21,0,0,0
0,0,0,0,0,7,0,0,0,0,0,7,21,21,0,0,0
0,0,0,0,21,21,2,2,2,2,2,21,21,0,0,0,0
0,0,0,0,0,21,21,21,21,21,21,21,0,0,0,0,0
0,0,0,0,0,0,0,0,0,0,0,0,0,0,0,0,0
0,0,0,0,0,0,0,0,0,0,0,0,0,0,0,0,0
0,0,0,7,0,0,0,0,0,0,0,0,0,0,0,0,0
endlayer

layer
0,0,0,33,0,0,0,0,0,0,0,0,0,0,0,0,0
0,0,0,31,0,0,0,0,0,0,0,0,0,0,0,0,0
0,0,0,0,0,0,0,0,0,0,0,0,0,0,0,0,0
0,0,0,0,0,0,0,0,0,0,0,0,0,0,0,0,0
0,0,0,0,0,0,2,2,14,2,2,0,0,0,0,0,0
0,0,0,0,0,7,0,0,0,0,0,7,0,0,0,0,0
0,0,0,0,2,0,0,0,0,0,0,0,2,0,0,0,0
0,0,0,0,2,0,0,0,0,0,0,0,2,0,0,0,0
0,0,0,0,0,7,0,0,0,0,0,7,0,0,0,0,0
0,0,0,0,0,0,2,2,14,2,2,0,0,0,0,0,0
0,0,0,0,0,0,0,0,0,0,0,0,0,0,0,0,0
0,0,0,0,0,0,0,0,0,0,0,0,0,0,0,0,0
0,0,0,7,0,0,0,0,0,0,0,0,0,0,0,0,0
0,0,0,33,0,0,0,0,0,0,0,0,0,0,0,0,0
endlayer

layer
0,0,0,7,0,0,0,0,0,0,0,0,0,0,0,0,0
0,0,0,33,0,0,0,0,0,0,0,0,0,0,0,0,0
0,0,0,31,0,0,0,0,0,0,0,0,0,0,0,0,0
0,0,0,0,0,0,0,0,0,0,0,0,0,0,0,0,0
0,0,0,0,0,0,2,2,14,2,2,0,0,0,0,0,0
0,0,0,0,0,7,0,0,0,0,0,7,0,0,0,0,0
0,0,0,0,2,0,0,0,0,0,0,0,2,0,0,0,0
0,0,0,0,2,0,0,0,0,0,0,0,2,0,0,0,0
0,0,0,0,0,7,0,0,0,0,0,7,0,0,0,0,0
0,0,0,0,0,0,2,2,14,2,2,0,0,0,0,0,0
0,0,0,0,0,0,0,0,0,0,0,0,0,0,0,0,0
0,0,0,7,0,0,0,0,0,0,0,0,0,0,0,0,0
0,0,0,33,0,0,0,0,0,0,0,0,0,0,0,0,0
0,0,0,31,0,0,0,0,0,0,0,0,0,0,0,0,0
endlayer

layer
0,0,0,0,0,0,0,0,0,0,0,0,0,0,0,0,0
0,0,0,7,0,0,0,0,0,0,0,0,0,0,0,0,0
0,0,0,33,0,0,0,0,0,0,0,0,0,0,0,0,0
0,0,0,31,0,0,0,0,0,0,0,0,0,0,0,0,0
0,0,0,0,0,0,32,2,2,2,0,0,0,0,0,0,0
0,0,0,0,0,7,34,34,34,34,34,7,0,0,0,0,0
0,0,0,0,2,19,4,4,4,4,4,19,2,0,0,0,0
0,0,0,0,2,19,4,4,4,4,4,19,2,0,0,0,0
0,0,0,0,0,7,34,34,34,34,34,7,0,0,0,0,0
0,0,0,0,0,0,32,2,2,2,32,0,0,0,0,0,0
0,0,0,7,0,0,0,0,0,0,0,0,0,0,0,0,0
0,0,0,33,0,0,0,0,0,0,0,0,0,0,0,0,0
0,0,0,31,0,0,0,0,0,0,0,0,0,0,0,0,0
0,0,0,0,0,0,0,0,0,0,0,0,0,0,0,0,0
endlayer

layer
0,0,0,0,0,0,0,0,0,0,0,0,0,0,0,0,0
0,0,0,0,0,0,0,0,0,0,0,0,0,0,0,0,0
0,0,0,7,0,0,0,0,0,0,0,0,0,0,0,0,0
0,0,0,33,0,0,0,0,0,0,0,0,0,0,0,0,0
0,0,0,31,0,0,0,32,32,32,0,0,0,0,0,0,0
0,0,0,0,0,32,32,21,21,21,32,32,0,0,0,0,0
0,0,0,0,0,21,2,2,2,2,2,21,32,0,0,0,0
0,0,0,0,0,21,2,2,2,2,2,21,32,0,0,0,0
0,0,0,0,0,32,32,21,21,21,32,0,0,0,0,0,0
0,0,0,7,0,0,0,32,32,32,0,0,0,0,0,0,0
0,0,0,33,0,0,0,0,0,0,0,0,0,0,0,0,0
0,0,0,31,0,0,0,0,0,0,0,0,0,0,0,0,0
0,0,0,0,0,0,0,0,0,0,0,0,0,0,0,0,0
0,0,0,0,0,0,0,0,0,0,0,0,0,0,0,0,0
endlayer

layer
0,0,0,0,0,0,0,0,0,0,0,0,0,0,0,0,0
0,0,0,0,0,0,0,0,0,0,0,0,0,0,0,0,0
0,0,0,0,0,0,0,0,0,0,0,0,0,0,0,0,0
0,0,0,7,0,0,0,0,0,0,0,0,0,0,0,0,0
0,0,0,33,0,0,0,0,0,0,0,0,0,0,0,0,0
0,0,0,31,0,0,0,0,0,0,0,0,0,0,0,0,0
0,0,0,0,0,0,5,5,5,5,5,0,0,0,0,0,0
0,0,0,0,0,0,5,5,5,5,5,0,0,0,0,0,0
0,0,0,7,0,0,0,0,0,0,0,0,0,0,0,0,0
0,0,0,33,0,0,0,0,0,0,0,0,0,0,0,0,0
0,0,0,31,0,0,0,0,0,0,0,0,0,0,0,0,0
0,0,0,0,0,0,0,0,0,0,0,0,0,0,0,0,0
0,0,0,0,0,0,0,0,0,0,0,0,0,0,0,0,0
0,0,0,0,0,0,0,0,0,0,0,0,0,0,0,0,0
endlayer

layer
0,0,0,0,0,0,0,0,0,0,0,0,0,0,0,0,0
0,0,0,0,0,0,0,0,0,0,0,0,0,0,0,0,0
0,0,0,0,0,0,0,0,0,0,0,0,0,0,0,0,0
0,0,0,0,0,0,0,0,0,0,0,0,0,0,0,0,0
0,0,0,7,0,0,0,0,0,0,0,0,0,0,0,0,0
0,0,0,33,0,0,0,0,0,0,0,0,0,0,0,0,0
0,0,2,31,0,0,18,18,18,18,18,0,0,0,0,0,0
0,0,7,7,0,0,36,35,35,35,6,0,0,0,0,0,0
0,0,0,33,0,0,0,0,0,0,0,0,0,0,0,0,0
0,0,0,31,0,0,0,0,0,0,0,0,0,0,0,0,0
0,0,0,0,0,0,0,0,0,0,0,0,0,0,0,0,0
0,0,0,0,0,0,0,0,0,0,0,0,0,0,0,0,0
0,0,0,0,0,0,0,0,0,0,0,0,0,0,0,0,0
0,0,0,0,0,0,0,0,0,0,0,0,0,0,0,0,0
endlayer

layer
0,0,0,0,0,0,0,0,0,0,0,0,0,0,0,0,0
0,0,0,0,0,0,0,0,0,0,0,0,0,0,0,0,0
0,0,0,0,0,0,0,0,0,0,0,0,0,0,0,0,0
0,0,0,0,0,0,0,0,0,0,0,0,0,0,0,0,0
0,0,0,0,0,0,0,0,0,0,0,0,0,0,0,0,0
0,0,2,7,0,0,0,0,0,0,0,0,0,0,0,0,0
0,21,7,37,37,37,37,37,37,37,37,0,0,0,0,0,0
0,21,7,37,37,37,37,37,37,37,37,0,0,0,0,0,0
0,0,2,31,0,0,0,0,0,0,0,0,0,0,0,0,0
0,0,0,0,0,0,0,0,0,0,0,0,0,0,0,0,0
0,0,0,0,0,0,0,0,0,0,0,0,0,0,0,0,0
0,0,0,0,0,0,0,0,0,0,0,0,0,0,0,0,0
0,0,0,0,0,0,0,0,0,0,0,0,0,0,0,0,0
0,0,0,0,0,0,0,0,0,0,0,0,0,0,0,0,0
endlayer

layer
0,0,0,0,0,0,0,0,0,0,0,0,0,0,0,0,0
0,0,0,0,0,0,0,0,0,0,0,0,0,0,0,0,0
0,0,0,0,0,0,0,0,0,0,0,0,0,0,0,0,0
0,0,0,0,0,0,0,0,0,0,0,0,0,0,0,0,0
0,0,0,0,0,0,0,0,0,0,0,0,0,0,0,0,0
0,0,32,31,0,0,0,0,0,0,0,0,0,0,0,0,0
0,0,7,7,0,0,0,0,0,0,0,0,0,0,0,0,0
0,0,2,7,0,0,0,0,0,0,0,0,0,0,0,0,0
0,0,32,7,0,0,0,0,0,0,0,0,0,0,0,0,0
0,0,0,0,0,0,0,0,0,0,0,0,0,0,0,0,0
0,0,0,0,0,0,0,0,0,0,0,0,0,0,0,0,0
0,0,0,0,0,0,0,0,0,0,0,0,0,0,0,0,0
0,0,0,0,0,0,0,0,0,0,0,0,0,0,0,0,0
0,0,0,0,0,0,0,0,0,0,0,0,0,0,0,0,0
endlayer

layer
0,0,0,0,0,0,0,0,0,0,0,0,0,0,0,0,0
0,0,0,0,0,0,0,0,0,0,0,0,0,0,0,0,0
0,0,0,0,0,0,0,0,0,0,0,0,0,0,0,0,0
0,0,0,0,0,0,0,0,0,0,0,0,0,0,0,0,0
0,0,0,31,0,0,0,0,0,0,0,0,0,0,0,0,0
0,0,0,33,0,0,0,0,0,0,0,0,0,0,0,0,0
0,0,32,7,0,0,0,0,0,0,0,0,0,0,0,0,0
0,0,32,32,0,0,0,0,0,0,0,0,0,0,0,0,0
0,0,0,33,0,0,0,0,0,0,0,0,0,0,0,0,0
0,0,0,7,0,0,0,0,0,0,0,0,0,0,0,0,0
0,0,0,0,0,0,0,0,0,0,0,0,0,0,0,0,0
0,0,0,0,0,0,0,0,0,0,0,0,0,0,0,0,0
0,0,0,0,0,0,0,0,0,0,0,0,0,0,0,0,0
0,0,0,0,0,0,0,0,0,0,0,0,0,0,0,0,0
endlayer

layer
0,0,0,0,0,0,0,0,0,0,0,0,0,0,0,0,0
0,0,0,0,0,0,0,0,0,0,0,0,0,0,0,0,0
0,0,0,0,0,0,0,0,0,0,0,0,0,0,0,0,0
0,0,0,31,0,0,0,0,0,0,0,0,0,0,0,0,0
0,0,0,33,0,0,0,0,0,0,0,0,0,0,0,0,0
0,0,0,7,0,0,0,0,0,0,0,0,0,0,0,0,0
0,0,0,32,0,0,0,0,0,0,0,0,0,0,0,0,0
0,0,0,0,0,0,0,0,0,0,0,0,0,0,0,0,0
0,0,0,31,0,0,0,0,0,0,0,0,0,0,0,0,0
0,0,0,33,0,0,0,0,0,0,0,0,0,0,0,0,0
0,0,0,7,0,0,0,0,0,0,0,0,0,0,0,0,0
0,0,0,0,0,0,0,0,0,0,0,0,0,0,0,0,0
0,0,0,0,0,0,0,0,0,0,0,0,0,0,0,0,0
0,0,0,0,0,0,0,0,0,0,0,0,0,0,0,0,0
endlayer

layer
0,0,0,0,0,0,0,0,0,0,0,0,0,0,0,0,0
0,0,0,0,0,0,0,0,0,0,0,0,0,0,0,0,0
0,0,0,31,0,0,0,0,0,0,0,0,0,0,0,0,0
0,0,0,33,0,0,0,0,0,0,0,0,0,0,0,0,0
0,0,0,7,0,0,0,0,0,0,0,0,0,0,0,0,0
0,0,0,32,0,0,0,0,0,0,0,0,0,0,0,0,0
0,0,0,0,0,0,0,0,0,0,0,0,0,0,0,0,0
0,0,0,0,0,0,0,0,0,0,0,0,0,0,0,0,0
0,0,0,32,0,0,0,0,0,0,0,0,0,0,0,0,0
0,0,0,31,0,0,0,0,0,0,0,0,0,0,0,0,0
0,0,0,33,0,0,0,0,0,0,0,0,0,0,0,0,0
0,0,0,7,0,0,0,0,0,0,0,0,0,0,0,0,0
0,0,0,0,0,0,0,0,0,0,0,0,0,0,0,0,0
0,0,0,0,0,0,0,0,0,0,0,0,0,0,0,0,0
endlayer

layer
0,0,0,0,0,0,0,0,0,0,0,0,0,0,0,0,0
0,0,0,31,0,0,0,0,0,0,0,0,0,0,0,0,0
0,0,0,33,0,0,0,0,0,0,0,0,0,0,0,0,0
0,0,0,7,0,0,0,0,0,0,0,0,0,0,0,0,0
0,0,0,32,0,0,0,0,0,0,0,0,0,0,0,0,0
0,0,0,0,0,0,0,0,0,0,0,0,0,0,0,0,0
0,0,0,0,0,0,0,0,0,0,0,0,0,0,0,0,0
0,0,0,0,0,0,0,0,0,0,0,0,0,0,0,0,0
0,0,0,0,0,0,0,0,0,0,0,0,0,0,0,0,0
0,0,0,32,0,0,0,0,0,0,0,0,0,0,0,0,0
0,0,0,31,0,0,0,0,0,0,0,0,0,0,0,0,0
0,0,0,33,0,0,0,0,0,0,0,0,0,0,0,0,0
0,0,0,7,0,0,0,0,0,0,0,0,0,0,0,0,0
0,0,0,0,0,0,0,0,0,0,0,0,0,0,0,0,0
endlayer

layer
0,0,0,31,0,0,0,0,0,0,0,0,0,0,0,0,0
0,0,0,33,0,0,0,0,0,0,0,0,0,0,0,0,0
0,0,0,7,0,0,0,0,0,0,0,0,0,0,0,0,0
0,0,0,0,0,0,0,0,0,0,0,0,0,0,0,0,0
0,0,0,0,0,0,0,0,0,0,0,0,0,0,0,0,0
0,0,0,0,0,0,0,0,0,0,0,0,0,0,0,0,0
0,0,0,0,0,0,0,0,0,0,0,0,0,0,0,0,0
0,0,0,0,0,0,0,0,0,0,0,0,0,0,0,0,0
0,0,0,0,0,0,0,0,0,0,0,0,0,0,0,0,0
0,0,0,0,0,0,0,0,0,0,0,0,0,0,0,0,0
0,0,0,32,0,0,0,0,0,0,0,0,0,0,0,0,0
0,0,0,31,0,0,0,0,0,0,0,0,0,0,0,0,0
0,0,0,33,0,0,0,0,0,0,0,0,0,0,0,0,0
0,0,0,7,0,0,0,0,0,0,0,0,0,0,0,0,0
endlayer

layer
0,0,0,33,0,0,0,0,0,0,0,0,0,0,0,0,0
0,0,0,7,0,0,0,0,0,0,0,0,0,0,0,0,0
0,0,0,32,0,0,0,0,0,0,0,0,0,0,0,0,0
0,0,0,0,0,0,0,0,0,0,0,0,0,0,0,0,0
0,0,0,0,0,0,0,0,0,0,0,0,0,0,0,0,0
0,0,0,0,0,0,0,0,0,0,0,0,0,0,0,0,0
0,0,0,0,0,0,0,0,0,0,0,0,0,0,0,0,0
0,0,0,0,0,0,0,0,0,0,0,0,0,0,0,0,0
0,0,0,0,0,0,0,0,0,0,0,0,0,0,0,0,0
0,0,0,0,0,0,0,0,0,0,0,0,0,0,0,0,0
0,0,0,0,0,0,0,0,0,0,0,0,0,0,0,0,0
0,0,0,32,0,0,0,0,0,0,0,0,0,0,0,0,0
0,0,0,31,0,0,0,0,0,0,0,0,0,0,0,0,0
0,0,0,33,0,0,0,0,0,0,0,0,0,0,0,0,0
endlayer

layer
0,0,0,7,0,0,0,0,0,0,0,0,0,0,0,0,0
0,0,0,32,0,0,0,0,0,0,0,0,0,0,0,0,0
0,0,0,0,0,0,0,0,0,0,0,0,0,0,0,0,0
0,0,0,0,0,0,0,0,0,0,0,0,0,0,0,0,0
0,0,0,0,0,0,0,0,0,0,0,0,0,0,0,0,0
0,0,0,0,0,0,0,0,0,0,0,0,0,0,0,0,0
0,0,0,0,0,0,0,0,0,0,0,0,0,0,0,0,0
0,0,0,0,0,0,0,0,0,0,0,0,0,0,0,0,0
0,0,0,0,0,0,0,0,0,0,0,0,0,0,0,0,0
0,0,0,0,0,0,0,0,0,0,0,0,0,0,0,0,0
0,0,0,0,0,0,0,0,0,0,0,0,0,0,0,0,0
0,0,0,0,0,0,0,0,0,0,0,0,0,0,0,0,0
0,0,0,32,0,0,0,0,0,0,0,0,0,0,0,0,0
0,0,0,31,0,0,0,0,0,0,0,0,0,0,0,0,0
endlayer

layer
0,0,0,32,0,0,0,0,0,0,0,0,0,0,0,0,0
0,0,0,0,0,0,0,0,0,0,0,0,0,0,0,0,0
0,0,0,0,0,0,0,0,0,0,0,0,0,0,0,0,0
0,0,0,0,0,0,0,0,0,0,0,0,0,0,0,0,0
0,0,0,0,0,0,0,0,0,0,0,0,0,0,0,0,0
0,0,0,0,0,0,0,0,0,0,0,0,0,0,0,0,0
0,0,0,0,0,0,0,0,0,0,0,0,0,0,0,0,0
0,0,0,0,0,0,0,0,0,0,0,0,0,0,0,0,0
0,0,0,0,0,0,0,0,0,0,0,0,0,0,0,0,0
0,0,0,0,0,0,0,0,0,0,0,0,0,0,0,0,0
0,0,0,0,0,0,0,0,0,0,0,0,0,0,0,0,0
0,0,0,0,0,0,0,0,0,0,0,0,0,0,0,0,0
0,0,0,0,0,0,0,0,0,0,0,0,0,0,0,0,0
0,0,0,32,0,0,0,0,0,0,0,0,0,0,0,0,0
endlayer

