
# Created by Ruins mod version 14.4 Ingame Parser
# authoring Player: Drock1994

weight=1
embed_into_distance=0
acceptable_target_blocks=
unacceptable_target_blocks=flowing_water,water,flowing_lava,lava
dimensions=16,21,17
allowable_overhang=0
max_leveling=2
leveling_buffer=0
preserve_water=0
preserve_lava=0

rule1=0,100,minecraft:sand-0
rule2=0,100,ForgeMultipart:block-0
rule3=0,100,minecraft:dark_oak_stairs-0
rule4=0,100,minecraft:planks-5
rule5=0,100,chisel:marble-5
rule6=0,100,CarpentersBlocks:blockCarpentersLadder-5
rule7=0,100,chisel:woolen_clay-15
rule8=0,100,chisel:glass_pane-2
rule9=0,100,EnderIO:blockFusedQuartz-1
rule10=0,100,CarpentersBlocks:blockCarpentersGarageDoor-6
rule11=0,100,chisel:marble-11
rule12=0,100,cfm:coffetablestone-2
rule13=0,100,cfm:couch-3
rule14=0,100,minecraft:dark_oak_stairs-3
rule15=0,100,cfm:hedge-1
rule16=2,100,minecraft:torch-1
rule17=2,100,minecraft:torch-3
rule18=2,100,minecraft:torch-4
rule19=2,100,minecraft:torch-2
rule20=0,100,CarpentersBlocks:blockCarpentersBed-0
rule21=0,100,ChestGenHook:dungeonChest:5-4
rule22=0,100,cfm:bedsidecabinet-3
rule23=0,100,ExtraUtilities:curtains-0
rule24=0,100,cfm:lampoff-0

layer
1,1,1,1,1,1,1,1,1,1,1,1,1,1,1,1,1
1,1,1,1,1,1,1,1,1,1,1,1,1,1,1,1,1
1,1,1,1,1,1,1,1,1,1,1,1,1,1,1,1,1
1,1,1,1,1,1,1,1,1,1,1,1,1,1,1,1,1
1,1,1,1,1,1,1,1,1,1,1,1,1,1,1,1,1
1,1,1,1,1,1,1,1,1,1,1,1,1,1,1,1,1
1,1,1,1,1,1,1,1,1,1,1,1,1,1,1,1,1
1,1,1,1,1,1,1,1,1,1,1,1,1,1,1,1,1
1,1,1,1,1,1,1,1,1,1,1,1,1,1,1,1,1
1,1,1,1,1,1,1,1,1,1,1,1,1,1,1,1,1
1,1,1,1,1,1,1,1,1,1,1,1,1,1,1,1,1
1,1,1,1,1,1,1,1,1,1,1,1,1,1,1,1,1
1,1,1,1,1,1,1,1,1,1,1,1,1,1,1,1,1
1,1,1,1,1,1,1,1,1,1,1,1,1,1,1,1,1
1,1,1,1,1,1,1,1,1,1,1,1,1,1,1,1,1
1,1,1,1,1,1,1,1,1,1,1,1,1,1,1,1,1
1,1,1,1,1,1,1,1,1,1,1,1,1,1,1,1,1
1,1,1,1,1,1,1,1,1,1,1,1,1,1,1,1,1
1,1,1,1,1,1,1,1,1,1,1,1,1,1,1,1,1
1,1,1,1,1,1,1,1,1,1,1,1,1,1,1,1,1
1,1,1,1,1,1,1,1,1,1,1,1,1,1,1,1,1
endlayer

layer
0,0,0,0,0,0,0,0,0,0,0,0,0,0,0,0,0
0,0,2,3,2,0,0,0,0,0,0,0,0,0,0,0,0
0,0,2,4,2,0,0,0,0,0,0,0,0,0,0,0,0
0,0,2,4,2,0,0,0,0,0,0,0,0,0,0,0,0
0,5,6,6,6,6,6,6,6,6,6,6,6,6,6,5,0
0,6,0,0,0,0,0,0,0,0,0,0,0,0,0,6,0
0,6,0,0,0,0,0,0,0,0,0,0,0,0,0,6,0
0,6,0,0,0,0,0,0,0,0,0,0,0,0,0,6,0
0,6,0,0,0,0,0,0,0,0,0,0,0,0,0,6,0
0,6,0,0,0,0,0,0,0,0,0,0,0,0,0,6,0
0,6,0,0,0,0,0,0,0,0,0,0,0,0,0,6,0
0,6,0,0,0,0,0,0,0,0,0,0,0,0,0,6,0
0,6,0,0,0,0,0,0,0,0,0,0,0,0,0,6,0
0,6,0,0,0,0,0,0,0,0,0,0,0,0,0,6,0
0,6,0,0,0,0,0,0,0,0,0,0,0,0,0,6,0
0,6,0,0,0,0,0,0,0,0,0,0,0,0,0,6,0
0,6,0,0,0,0,0,0,0,0,0,0,0,0,0,6,0
0,6,0,0,0,0,0,0,0,0,0,0,0,0,0,6,0
0,6,0,0,0,0,0,0,0,0,0,0,0,0,0,6,0
0,5,6,6,6,6,6,6,6,6,6,6,6,6,6,5,0
0,0,0,0,0,0,0,0,0,0,0,0,0,0,0,0,0
endlayer

layer
0,0,0,0,0,0,0,0,0,0,0,0,0,0,0,0,0
0,0,0,0,0,0,0,0,0,0,0,0,0,0,0,0,0
0,0,2,3,2,0,0,0,0,0,0,0,0,0,0,0,0
0,0,2,4,2,0,0,0,0,0,0,0,0,0,0,0,0
0,5,5,5,5,5,5,5,5,5,5,5,5,5,5,5,0
0,5,0,0,0,0,0,0,0,0,0,0,0,0,0,5,0
0,5,0,0,0,0,0,0,0,0,0,0,0,0,0,5,0
0,5,0,0,0,0,0,0,0,0,0,0,0,0,0,5,0
0,5,0,0,0,0,0,0,0,0,0,0,0,0,0,5,0
0,5,0,0,0,0,0,0,0,0,0,0,0,0,0,5,0
0,5,0,0,0,0,0,0,0,0,0,0,0,0,0,5,0
0,5,0,0,0,0,0,0,0,0,0,0,0,0,0,5,0
0,5,0,0,0,0,0,0,0,0,0,0,0,0,0,5,0
0,5,0,0,0,0,0,0,0,0,0,0,0,0,0,5,0
0,5,0,0,0,0,0,0,0,0,0,0,0,0,0,5,0
0,5,0,0,0,0,0,0,0,0,0,0,0,0,0,5,0
0,5,0,0,0,0,0,0,0,0,0,0,0,0,0,5,0
0,5,0,0,0,0,0,0,0,0,0,0,0,0,0,5,0
0,5,0,0,0,0,0,0,0,0,0,0,0,0,0,5,0
0,5,5,5,5,5,5,5,5,5,5,5,5,5,5,5,0
0,0,0,0,0,0,0,0,0,0,0,0,0,0,0,0,0
endlayer

layer
0,0,0,0,0,0,0,0,0,0,0,0,0,0,0,0,0
0,0,0,0,0,0,0,0,0,0,0,0,0,0,0,0,0
0,0,0,0,0,0,0,0,0,0,0,0,0,0,0,0,0
2,2,2,3,2,2,2,2,2,2,2,2,2,2,2,2,2
2,5,5,5,5,5,5,5,5,5,5,5,5,5,5,5,2
2,5,4,4,4,4,4,4,4,4,4,4,4,4,4,5,2
2,5,4,4,4,4,4,4,4,4,4,4,4,4,4,5,2
2,5,4,4,4,4,4,4,4,4,4,4,4,4,4,5,2
2,5,4,4,4,4,4,4,4,4,4,4,4,4,4,5,2
2,5,7,7,7,7,7,7,7,7,7,7,7,7,7,5,2
2,5,7,7,7,7,7,7,7,7,7,7,7,7,7,5,2
2,5,7,7,7,7,7,7,7,7,7,7,7,7,7,5,2
2,5,7,7,7,7,7,7,7,7,7,7,7,7,7,5,2
2,5,7,7,7,7,7,7,7,7,7,7,7,7,7,5,2
2,5,7,7,7,7,7,7,7,7,7,7,7,7,7,5,2
2,5,7,7,7,7,7,7,7,7,7,7,7,7,7,5,2
2,5,7,7,7,7,7,7,7,7,7,7,7,7,7,5,2
2,5,7,7,7,7,7,7,7,7,7,7,7,7,7,5,2
2,5,7,7,7,7,7,7,7,7,7,7,7,7,7,5,2
2,5,5,5,5,5,5,5,5,5,5,5,5,5,5,5,2
2,2,2,2,2,2,2,2,2,2,2,2,2,2,2,2,2
endlayer

layer
0,0,0,0,0,0,0,0,0,0,0,0,0,0,0,0,0
0,0,0,0,0,0,0,0,0,0,0,0,0,0,0,0,0
0,0,0,0,0,0,0,0,0,0,0,0,0,0,0,0,0
0,0,0,0,0,0,0,0,0,0,0,0,0,0,0,0,0
0,8,8,0,8,8,8,8,8,8,8,8,8,8,8,8,0
0,8,0,0,0,0,0,0,0,0,0,0,0,0,0,8,0
0,8,0,0,0,0,0,0,0,0,0,0,0,0,0,8,0
0,8,0,0,0,0,0,0,0,0,0,0,0,0,0,8,0
0,8,4,0,0,0,0,4,0,0,0,0,0,0,0,8,0
0,5,5,9,10,10,9,5,5,9,9,9,9,9,5,5,0
0,5,0,2,0,0,2,11,11,2,0,0,0,2,11,5,0
0,5,11,0,0,0,0,0,0,0,0,0,0,0,2,9,0
0,9,2,0,0,0,0,0,0,0,0,0,0,0,0,9,0
0,9,2,0,0,0,0,0,0,0,0,0,0,0,2,9,0
0,5,11,0,0,0,0,0,0,0,0,0,0,0,11,5,0
0,9,2,0,0,0,0,0,12,12,12,0,0,0,2,9,0
0,9,2,0,0,0,0,0,0,0,0,0,0,0,0,9,0
0,5,11,0,14,0,0,0,13,13,13,0,4,0,2,9,0
0,5,11,11,11,11,11,11,11,11,11,11,11,11,0,5,0
0,5,5,5,5,5,5,5,5,5,5,5,5,5,5,5,0
0,0,0,0,0,0,0,0,0,0,0,0,0,0,0,0,0
endlayer

layer
0,0,0,0,0,0,0,0,0,0,0,0,0,0,0,0,0
0,0,0,0,0,0,0,0,0,0,0,0,0,0,0,0,0
0,0,0,0,0,0,0,0,0,0,0,0,0,0,0,0,0
0,0,0,0,0,0,0,0,0,0,0,0,0,0,0,0,0
0,0,0,0,0,0,0,0,0,0,0,0,8,8,8,8,0
0,0,0,0,0,0,0,0,0,0,0,0,0,0,0,8,0
0,0,0,0,0,0,0,0,0,0,0,0,0,0,0,8,0
0,0,0,0,0,0,0,0,0,0,0,0,0,0,0,8,0
0,0,15,0,0,0,0,15,0,0,0,0,0,0,0,8,0
0,5,5,9,10,10,9,5,5,9,9,9,9,9,5,5,0
0,5,0,2,0,0,2,11,11,2,0,0,0,2,11,5,0
0,5,11,0,0,0,0,0,0,0,0,0,0,0,2,9,0
0,9,2,0,0,0,0,0,0,0,0,0,0,0,0,9,0
0,9,2,0,0,0,0,0,0,0,0,0,0,0,2,9,0
0,5,11,0,0,0,0,0,0,0,0,0,0,0,11,5,0
0,9,2,0,0,0,0,0,0,0,0,0,0,0,2,9,0
0,9,2,0,0,0,0,0,0,0,0,0,0,0,0,9,0
0,5,11,0,0,14,0,0,0,0,0,0,15,0,2,9,0
0,5,11,11,11,11,11,11,11,11,11,11,11,11,0,5,0
0,5,5,5,5,5,5,5,5,5,5,5,5,5,5,5,0
0,0,0,0,0,0,0,0,0,0,0,0,0,0,0,0,0
endlayer

layer
0,0,0,0,0,0,0,0,0,0,0,0,0,0,0,0,0
0,0,0,0,0,0,0,0,0,0,0,0,0,0,0,0,0
0,0,0,0,0,0,0,0,0,0,0,0,0,0,0,0,0
0,0,0,0,0,0,0,0,0,0,0,0,0,0,0,0,0
0,0,0,0,0,0,0,0,0,0,0,0,0,0,0,0,0
0,0,0,0,0,0,0,0,0,0,0,0,0,0,0,0,0
0,0,2,2,2,2,2,2,0,0,0,0,0,0,0,0,0
0,0,2,2,2,2,2,2,0,0,0,0,0,0,0,0,0
0,0,2,2,2,2,2,2,0,0,0,0,0,0,0,0,0
0,5,5,9,10,10,9,5,5,9,9,9,9,9,5,5,0
0,5,0,2,2,2,2,11,11,2,0,0,0,2,11,5,0
0,5,11,0,0,0,0,0,16,0,0,0,0,0,2,9,0
0,9,2,0,0,0,0,0,0,0,0,0,0,0,0,9,0
0,9,2,0,0,0,0,0,0,0,0,0,0,0,2,9,0
0,5,11,18,0,0,0,0,0,0,0,0,0,17,11,5,0
0,9,2,0,0,0,0,0,0,0,0,0,0,0,2,9,0
0,9,2,0,0,0,0,0,0,0,0,0,0,0,0,9,0
0,5,11,0,0,0,14,0,19,0,0,0,0,0,2,9,0
0,5,11,11,11,11,11,11,11,11,11,11,11,11,0,5,0
0,5,5,5,5,5,5,5,5,5,5,5,5,5,5,5,0
0,0,0,0,0,0,0,0,0,0,0,0,0,0,0,0,0
endlayer

layer
0,0,0,0,0,0,0,0,0,0,0,0,0,0,0,0,0
0,0,0,0,0,0,0,0,0,0,0,0,0,0,0,0,0
0,0,0,0,0,0,0,0,0,0,0,0,0,0,0,0,0
0,0,0,0,0,0,0,0,0,0,0,0,0,0,0,0,0
0,0,0,0,0,0,0,0,0,0,0,0,0,0,0,0,0
0,0,0,0,0,0,0,0,0,0,0,0,0,0,0,0,0
0,0,2,2,2,2,2,2,2,2,2,2,2,2,2,0,0
0,0,2,2,2,2,2,2,2,2,2,2,2,2,2,0,0
2,2,2,2,2,2,2,2,2,2,2,2,2,2,2,2,2
2,5,5,5,5,5,5,5,5,9,9,9,9,9,5,5,2
2,5,11,11,11,11,11,11,11,2,2,2,2,2,11,5,2
2,5,11,11,11,11,11,11,11,0,0,0,0,0,2,9,0
2,5,11,11,11,11,11,11,11,0,0,0,0,0,2,9,0
2,5,11,11,11,11,11,11,11,0,0,0,0,0,2,9,0
2,5,11,11,11,11,11,11,11,0,0,0,0,0,11,5,2
2,5,11,11,11,11,11,11,11,0,0,0,0,0,2,9,0
2,5,11,11,11,11,11,11,11,0,0,0,0,0,2,9,0
2,5,11,0,0,0,0,14,11,0,0,0,0,0,2,9,0
2,5,11,11,11,11,11,11,11,11,11,11,11,11,0,5,2
2,5,5,5,5,5,5,5,5,5,5,5,5,5,5,5,2
2,2,2,2,2,2,2,2,2,2,2,2,2,2,2,2,2
endlayer

layer
0,0,0,0,0,0,0,0,0,0,0,0,0,0,0,0,0
0,0,0,0,0,0,0,0,0,0,0,0,0,0,0,0,0
0,0,0,0,0,0,0,0,0,0,0,0,0,0,0,0,0
0,0,0,0,0,0,0,0,0,0,0,0,0,0,0,0,0
0,0,0,0,0,0,0,0,0,0,0,0,0,0,0,0,0
0,0,0,0,0,0,0,0,0,0,0,0,0,0,0,0,0
0,0,0,0,0,0,0,0,2,2,2,2,2,2,2,0,0
0,0,0,0,0,0,0,0,2,2,2,2,2,2,2,0,0
2,2,2,2,2,2,2,2,2,2,2,2,2,2,2,2,2
2,5,5,5,5,5,5,5,5,5,5,5,5,5,5,5,2
2,5,11,11,11,11,11,11,11,11,11,11,11,11,11,5,2
2,5,11,11,11,11,11,11,11,11,11,11,11,11,11,5,2
2,5,11,11,11,11,11,11,11,11,11,11,11,11,11,5,2
2,5,11,11,11,11,11,11,11,11,11,11,11,11,11,5,2
2,5,11,11,11,11,11,11,11,11,11,11,11,11,11,5,2
2,5,11,11,11,11,11,11,11,11,11,11,11,11,11,5,2
2,5,11,11,11,11,11,11,11,11,11,11,11,11,11,5,2
2,5,11,11,0,0,0,0,14,11,11,11,11,11,11,5,2
2,5,11,11,11,11,11,11,11,11,11,11,11,11,11,5,2
2,5,5,5,5,5,5,5,5,5,5,5,5,5,5,5,2
2,2,2,2,2,2,2,2,2,2,2,2,2,2,2,2,2
endlayer

layer
0,0,0,0,0,0,0,0,0,0,0,0,0,0,0,0,0
0,0,0,0,0,0,0,0,0,0,0,0,0,0,0,0,0
0,0,0,0,0,0,0,0,0,0,0,0,0,0,0,0,0
0,0,0,0,0,0,0,0,0,0,0,0,0,0,0,0,0
0,0,0,0,0,0,0,0,0,0,0,0,0,0,0,0,0
0,0,0,0,0,0,0,0,0,0,0,0,0,0,0,0,0
0,0,0,0,0,0,0,0,0,0,0,0,0,0,0,0,0
0,0,0,0,0,0,0,0,0,0,0,0,0,0,0,0,0
0,0,0,0,0,0,0,0,0,0,0,0,0,0,0,0,0
0,5,5,5,5,5,5,5,5,5,5,5,5,5,5,5,0
0,5,5,5,5,5,5,5,5,5,5,5,5,5,5,5,0
0,5,5,5,5,5,5,5,5,5,5,5,5,5,5,5,0
0,5,5,5,5,5,5,5,5,5,5,5,5,5,5,5,0
0,5,5,5,5,5,5,5,5,5,5,5,5,5,5,5,0
0,5,5,5,5,5,5,5,5,5,5,5,5,5,5,5,0
0,5,5,5,5,5,5,5,5,5,5,5,5,5,5,5,0
0,5,5,5,5,5,5,5,5,5,5,5,5,5,5,5,0
0,5,5,5,11,0,0,0,0,14,5,5,5,5,5,5,0
0,5,5,5,11,11,11,11,11,11,11,11,11,11,5,5,0
0,5,5,5,5,5,5,5,5,5,5,5,5,5,5,5,0
0,0,0,0,0,0,0,0,0,0,0,0,0,0,0,0,0
endlayer

layer
0,0,0,0,0,0,0,0,0,0,0,0,0,0,0,0,0
0,0,0,0,0,0,0,0,0,0,0,0,0,0,0,0,0
0,0,0,0,0,0,0,0,0,0,0,0,0,0,0,0,0
0,0,0,0,0,0,0,0,0,0,0,0,0,0,0,0,0
0,0,0,0,0,0,0,0,0,0,0,0,0,0,0,0,0
0,0,0,0,0,0,0,0,0,0,0,0,0,0,0,0,0
0,0,0,0,0,0,0,0,0,0,0,0,0,0,0,0,0
0,0,0,0,0,0,0,0,0,0,0,0,0,0,0,0,0
0,0,0,0,0,0,0,0,0,0,0,0,0,0,0,0,0
0,8,8,8,8,8,8,4,8,8,8,8,8,8,8,4,0
0,8,0,0,0,0,0,0,0,0,0,0,0,0,0,5,0
0,8,0,0,0,0,0,0,0,0,0,0,0,0,0,9,0
0,5,5,9,9,9,9,5,0,0,0,0,0,0,0,9,0
0,5,0,0,0,0,0,0,0,0,0,0,0,0,0,9,0
0,5,0,0,20,20,0,0,0,0,0,0,0,0,0,9,0
0,5,0,22,20,20,22,0,0,0,0,21,21,0,4,5,0
0,5,11,11,11,11,11,11,11,23,11,11,11,11,11,5,0
0,5,0,0,11,11,18,0,0,0,11,11,11,11,11,5,0
0,5,21,21,11,11,11,11,11,11,11,11,11,11,11,5,0
0,5,5,5,5,5,5,5,5,5,5,5,5,5,5,5,0
0,0,0,0,0,0,0,0,0,0,0,0,0,0,0,0,0
endlayer

layer
0,0,0,0,0,0,0,0,0,0,0,0,0,0,0,0,0
0,0,0,0,0,0,0,0,0,0,0,0,0,0,0,0,0
0,0,0,0,0,0,0,0,0,0,0,0,0,0,0,0,0
0,0,0,0,0,0,0,0,0,0,0,0,0,0,0,0,0
0,0,0,0,0,0,0,0,0,0,0,0,0,0,0,0,0
0,0,0,0,0,0,0,0,0,0,0,0,0,0,0,0,0
0,0,0,0,0,0,0,0,0,0,0,0,0,0,0,0,0
0,0,0,0,0,0,0,0,0,0,0,0,0,0,0,0,0
0,0,0,0,0,0,0,0,0,0,0,0,0,0,0,0,0
0,0,0,0,0,0,0,2,0,0,0,0,0,0,0,2,0
0,0,0,0,0,0,0,0,0,0,0,0,0,0,0,5,0
0,0,0,0,0,0,0,0,0,0,0,0,0,0,0,9,0
0,5,5,9,9,9,9,5,0,0,0,0,0,0,0,9,0
0,5,0,0,0,0,0,0,0,0,0,0,0,0,0,9,0
0,5,0,0,0,0,0,0,0,0,0,0,0,0,0,9,0
0,5,0,24,0,0,24,0,0,0,0,0,0,0,15,5,0
0,5,11,11,11,11,11,11,11,23,11,11,11,11,11,5,0
0,5,0,0,11,11,11,0,0,0,11,11,11,11,11,5,0
0,5,0,0,11,11,11,11,11,11,11,11,11,11,11,5,0
0,5,5,5,5,5,5,5,5,5,5,5,5,5,5,5,0
0,0,0,0,0,0,0,0,0,0,0,0,0,0,0,0,0
endlayer

layer
0,0,0,0,0,0,0,0,0,0,0,0,0,0,0,0,0
0,0,0,0,0,0,0,0,0,0,0,0,0,0,0,0,0
0,0,0,0,0,0,0,0,0,0,0,0,0,0,0,0,0
0,0,0,0,0,0,0,0,0,0,0,0,0,0,0,0,0
0,0,0,0,0,0,0,0,0,0,0,0,0,0,0,0,0
0,0,0,0,0,0,0,0,0,0,0,0,0,0,0,0,0
0,0,0,0,0,0,0,0,0,0,0,0,0,0,0,0,0
0,0,0,0,0,0,0,0,0,0,0,0,0,0,0,0,0
0,0,0,0,0,0,0,0,0,0,0,0,0,0,0,0,0
0,0,2,2,2,2,2,2,0,0,0,0,0,0,0,2,0
0,0,2,2,2,2,2,2,0,0,0,0,0,0,0,5,0
0,0,2,2,2,2,2,2,0,0,0,0,0,0,0,9,0
0,5,5,9,9,9,9,5,0,0,0,0,0,0,0,9,0
0,5,0,0,0,0,0,0,0,0,0,0,0,0,0,9,0
0,5,0,0,0,0,0,0,0,0,0,0,0,0,0,9,0
0,5,0,0,0,0,0,0,0,0,0,0,0,0,0,5,0
0,5,11,11,11,11,11,11,11,11,11,11,11,11,11,5,0
0,5,5,5,11,11,11,11,11,11,11,11,11,11,11,5,0
0,5,5,5,11,11,11,11,11,11,11,11,11,11,11,5,0
0,5,5,5,5,5,5,5,5,5,5,5,5,5,5,5,0
0,0,0,0,0,0,0,0,0,0,0,0,0,0,0,0,0
endlayer

layer
0,0,0,0,0,0,0,0,0,0,0,0,0,0,0,0,0
0,0,0,0,0,0,0,0,0,0,0,0,0,0,0,0,0
0,0,0,0,0,0,0,0,0,0,0,0,0,0,0,0,0
0,0,0,0,0,0,0,0,0,0,0,0,0,0,0,0,0
0,0,0,0,0,0,0,0,0,0,0,0,0,0,0,0,0
0,0,0,0,0,0,0,0,0,0,0,0,0,0,0,0,0
0,0,0,0,0,0,0,0,0,0,0,0,0,0,0,0,0
0,0,0,0,0,0,0,0,0,0,0,0,0,0,0,0,0
0,0,0,0,0,0,0,0,0,0,0,0,0,0,0,0,0
0,0,2,2,2,2,2,2,0,0,0,0,0,0,0,2,0
0,0,2,2,2,2,2,2,0,0,0,0,0,0,0,5,2
0,2,2,2,2,2,2,2,0,0,0,0,0,0,0,5,2
2,5,5,5,5,5,5,5,0,0,0,0,0,0,0,5,2
2,5,0,0,0,0,0,0,0,0,0,0,0,0,0,5,2
2,5,0,0,0,0,0,0,0,0,0,0,0,0,0,5,2
2,5,0,0,0,0,0,0,0,0,0,0,0,0,0,5,2
2,5,11,11,11,11,11,11,11,11,11,11,11,11,11,5,2
2,5,5,5,11,11,11,11,11,11,11,11,11,11,11,5,2
2,5,5,5,11,11,11,11,11,11,11,11,11,11,11,5,2
2,5,5,5,5,5,5,5,5,5,5,5,5,5,5,5,2
0,2,2,2,2,2,2,2,2,2,2,2,2,2,2,2,0
endlayer

layer
0,0,0,0,0,0,0,0,0,0,0,0,0,0,0,0,0
0,0,0,0,0,0,0,0,0,0,0,0,0,0,0,0,0
0,0,0,0,0,0,0,0,0,0,0,0,0,0,0,0,0
0,0,0,0,0,0,0,0,0,0,0,0,0,0,0,0,0
0,0,0,0,0,0,0,0,0,0,0,0,0,0,0,0,0
0,0,0,0,0,0,0,0,0,0,0,0,0,0,0,0,0
0,0,0,0,0,0,0,0,0,0,0,0,0,0,0,0,0
0,0,0,0,0,0,0,0,0,0,0,0,0,0,0,0,0
0,0,0,0,0,0,0,2,2,2,2,2,2,2,2,2,0
0,0,0,0,0,0,0,2,2,2,2,2,2,2,2,2,0
0,0,0,0,0,0,0,2,2,2,2,2,2,2,2,2,0
0,2,2,2,2,2,2,2,2,2,2,2,2,2,2,2,0
2,5,5,5,5,5,5,5,2,2,2,2,2,2,2,2,0
2,5,5,5,5,5,5,5,2,2,2,2,2,2,2,2,0
2,5,5,5,5,5,5,5,2,2,2,2,2,2,2,2,0
2,5,5,5,5,5,5,5,2,2,2,2,2,2,2,2,0
2,5,5,5,5,5,5,5,5,5,5,5,5,5,5,5,2
2,5,5,5,5,5,5,5,5,5,5,5,5,5,5,5,2
2,5,5,5,5,5,5,5,5,5,5,5,5,5,5,5,2
2,5,5,5,5,5,5,5,5,5,5,5,5,5,5,5,2
0,2,2,2,2,2,2,2,2,2,2,2,2,2,2,2,0
endlayer

layer
0,0,0,0,0,0,0,0,0,0,0,0,0,0,0,0,0
0,0,0,0,0,0,0,0,0,0,0,0,0,0,0,0,0
0,0,0,0,0,0,0,0,0,0,0,0,0,0,0,0,0
0,0,0,0,0,0,0,0,0,0,0,0,0,0,0,0,0
0,0,0,0,0,0,0,0,0,0,0,0,0,0,0,0,0
0,0,0,0,0,0,0,0,0,0,0,0,0,0,0,0,0
0,0,0,0,0,0,0,0,0,0,0,0,0,0,0,0,0
0,0,0,0,0,0,0,0,0,0,0,0,0,0,0,0,0
0,0,0,0,0,0,0,2,2,2,2,2,2,2,2,2,0
0,0,0,0,0,0,0,2,2,2,2,2,2,2,2,2,0
0,0,0,0,0,0,0,2,2,2,2,2,2,2,2,2,0
0,0,0,0,0,0,0,2,2,2,2,2,2,2,2,2,0
0,0,0,0,0,0,0,2,2,2,2,2,2,2,2,2,0
0,0,0,0,0,0,0,2,2,2,2,2,2,2,2,2,0
0,0,0,0,0,0,0,2,2,2,2,2,2,2,2,2,0
0,0,0,0,0,0,0,2,2,2,2,2,2,2,2,2,0
0,0,0,0,0,0,0,5,5,5,5,5,5,5,5,5,0
0,0,0,0,0,0,0,5,5,5,5,5,5,5,5,5,0
0,0,0,0,0,0,0,5,5,5,5,5,5,5,5,5,0
0,0,0,0,0,0,0,5,5,5,5,5,5,5,5,5,0
0,0,0,0,0,0,0,0,0,0,0,0,0,0,0,0,0
endlayer

