
# Created by Ruins mod version 14.4 Ingame Parser
# authoring Player: Drock1994

weight=1
embed_into_distance=0
acceptable_target_blocks=
unacceptable_target_blocks=flowing_water,water,flowing_lava,lava
dimensions=7,19,19
allowable_overhang=0
max_leveling=2
leveling_buffer=0
preserve_water=0
preserve_lava=0

rule1=0,100,minecraft:water-0
rule2=0,100,minecraft:planks-1
rule3=0,100,minecraft:fence-0
rule4=0,100,minecraft:wooden_door-0
rule5=0,100,minecraft:carpet-15
rule6=0,100,minecraft:carpet-11
rule7=0,100,minecraft:wooden_door-1
rule8=0,100,minecraft:wooden_door-3
rule9=0,100,ChestGenHook:dungeonChest:5-4
rule10=0,100,minecraft:bed-3
rule11=0,100,minecraft:bed-11
rule12=0,100,minecraft:wooden_door-2
rule13=0,100,minecraft:iron_bars-0
rule14=0,100,minecraft:wooden_door-11
rule15=0,100,chisel:glowstone-10
rule16=0,100,minecraft:stone_stairs-2
rule17=0,100,minecraft:stone_stairs-0
rule18=0,100,minecraft:stone_stairs-3
rule19=0,100,minecraft:stone_stairs-1

layer
1,1,1,1,1,1,1,1,1,1,1,1,1,1,1,1,1,1,1
1,1,1,1,1,1,1,1,1,1,1,1,1,1,1,1,1,1,1
1,1,1,1,1,1,1,1,1,1,1,1,1,1,1,1,1,1,1
1,1,1,1,1,1,1,1,1,1,1,1,1,1,1,1,1,1,1
1,1,1,1,1,1,1,1,1,1,1,1,1,1,1,1,1,1,1
1,1,1,1,1,1,1,1,1,1,1,1,1,1,1,1,1,1,1
1,1,1,1,1,1,1,1,1,1,1,1,1,1,1,1,1,1,1
1,1,1,1,1,1,1,1,1,1,1,1,1,1,1,1,1,1,1
1,1,1,1,1,1,1,1,1,1,1,1,1,1,1,1,1,1,1
1,1,1,1,1,1,1,1,1,1,1,1,1,1,1,1,1,1,1
1,1,1,1,1,1,1,1,1,1,1,1,1,1,1,1,1,1,1
1,1,1,1,1,1,1,1,1,1,1,1,1,1,1,1,1,1,1
1,1,1,1,1,1,1,1,1,1,1,1,1,1,1,1,1,1,1
1,1,1,1,1,1,1,1,1,1,1,1,1,1,1,1,1,1,1
1,1,1,1,1,1,1,1,1,1,1,1,1,1,1,1,1,1,1
1,1,1,1,1,1,1,1,1,1,1,1,1,1,1,1,1,1,1
1,1,1,1,1,1,1,1,1,1,1,1,1,1,1,1,1,1,1
1,1,1,1,1,1,1,1,1,1,1,1,1,1,1,1,1,1,1
1,1,1,1,1,1,1,1,1,1,1,1,1,1,1,1,1,1,1
endlayer

layer
0,2,2,2,2,2,2,2,2,2,2,2,2,2,2,2,2,2,0
2,2,2,2,2,2,2,2,2,2,2,2,2,2,2,2,2,2,2
2,2,2,2,2,2,2,2,2,2,2,2,2,2,2,2,2,2,2
2,2,2,2,2,2,2,2,2,2,2,2,2,2,2,2,2,2,2
2,2,2,2,2,2,2,2,2,2,2,2,2,2,2,2,2,2,2
2,2,2,2,2,2,2,2,2,2,2,2,2,2,2,2,2,2,2
2,2,2,2,2,2,2,2,2,2,2,2,2,2,2,2,2,2,2
2,2,2,2,2,2,2,2,2,2,2,2,2,2,2,2,2,2,2
2,2,2,2,2,2,2,2,2,2,2,2,2,2,2,2,2,2,2
2,2,2,2,2,2,2,2,2,2,2,2,2,2,2,2,2,2,2
2,2,2,2,2,2,2,2,2,2,2,2,2,2,2,2,2,2,2
2,2,2,2,2,2,2,2,2,2,2,2,2,2,2,2,2,2,2
2,2,2,2,2,2,2,2,2,2,2,2,2,2,2,2,2,2,2
2,2,2,2,2,2,2,2,2,2,2,2,2,2,2,2,2,2,2
2,2,2,2,2,2,2,2,2,2,2,2,2,2,2,2,2,2,2
2,2,2,2,2,2,2,2,2,2,2,2,2,2,2,2,2,2,2
2,2,2,2,2,2,2,2,2,2,2,2,2,2,2,2,2,2,2
2,2,2,2,2,2,2,2,2,2,2,2,2,2,2,2,2,2,2
0,2,2,2,2,2,2,2,2,2,2,2,2,2,2,2,2,2,0
endlayer

layer
0,3,3,3,3,3,3,3,0,0,0,3,3,3,3,3,3,3,0
3,3,0,0,0,0,0,0,0,0,0,0,0,0,0,0,0,3,3
3,0,3,0,0,0,0,0,0,0,0,0,0,0,0,0,3,0,3
3,0,0,0,0,0,0,0,0,0,0,0,0,0,0,0,0,0,3
3,0,0,0,0,2,2,2,2,4,2,2,2,2,0,0,0,0,3
3,0,0,0,2,0,0,0,0,0,0,0,0,0,2,0,0,0,3
3,0,0,0,2,0,0,0,0,0,0,0,0,0,2,0,0,0,3
3,0,0,0,2,0,0,5,5,5,5,5,0,0,2,0,0,0,3
0,0,0,0,2,0,0,5,6,6,6,5,0,0,2,0,0,0,0
0,0,0,0,8,0,0,5,6,5,6,5,0,0,7,0,0,0,0
0,0,0,0,2,0,0,5,6,6,6,5,0,0,2,0,0,0,0
3,0,0,0,2,0,9,5,5,5,5,5,9,0,2,0,0,0,3
3,0,0,0,2,0,10,0,0,0,0,0,10,0,2,0,0,0,3
3,0,0,0,2,0,11,0,0,0,0,0,11,0,2,0,0,0,3
3,0,0,0,0,2,2,2,2,12,2,2,2,2,0,0,0,0,3
3,0,0,0,0,0,0,0,0,0,0,0,0,0,0,0,0,0,3
3,0,3,0,0,0,0,0,0,0,0,0,0,0,0,0,3,0,3
3,3,0,0,0,0,0,0,0,0,0,0,0,0,0,0,0,3,3
0,3,3,3,3,3,3,3,0,0,0,3,3,3,3,3,3,3,0
endlayer

layer
0,0,0,0,0,0,0,0,0,0,0,0,0,0,0,0,0,0,0
0,0,0,0,0,0,0,0,0,0,0,0,0,0,0,0,0,0,0
0,0,3,0,0,0,0,0,0,0,0,0,0,0,0,0,3,0,0
0,0,0,0,0,0,0,0,0,0,0,0,0,0,0,0,0,0,0
0,0,0,0,0,2,2,13,2,14,2,13,2,2,0,0,0,0,0
0,0,0,0,2,0,0,0,0,0,0,0,0,0,2,0,0,0,0
0,0,0,0,2,0,0,0,0,0,0,0,0,0,2,0,0,0,0
0,0,0,0,13,0,0,0,0,0,0,0,0,0,13,0,0,0,0
0,0,0,0,2,0,0,0,0,0,0,0,0,0,2,0,0,0,0
0,0,0,0,14,0,0,0,0,0,0,0,0,0,14,0,0,0,0
0,0,0,0,2,0,0,0,0,0,0,0,0,0,2,0,0,0,0
0,0,0,0,13,0,0,0,0,0,0,0,0,0,13,0,0,0,0
0,0,0,0,2,0,0,0,0,0,0,0,0,0,2,0,0,0,0
0,0,0,0,2,0,0,0,0,0,0,0,0,0,2,0,0,0,0
0,0,0,0,0,2,2,13,2,14,2,13,2,2,0,0,0,0,0
0,0,0,0,0,0,0,0,0,0,0,0,0,0,0,0,0,0,0
0,0,3,0,0,0,0,0,0,0,0,0,0,0,0,0,3,0,0
0,0,0,0,0,0,0,0,0,0,0,0,0,0,0,0,0,0,0
0,0,0,0,0,0,0,0,0,0,0,0,0,0,0,0,0,0,0
endlayer

layer
0,0,0,0,0,0,0,0,0,0,0,0,0,0,0,0,0,0,0
0,0,0,0,0,0,0,0,0,0,0,0,0,0,0,0,0,0,0
0,0,3,0,0,0,0,0,0,0,0,0,0,0,0,0,3,0,0
0,0,0,0,0,0,0,0,0,0,0,0,0,0,0,0,0,0,0
0,0,0,0,0,2,2,2,2,2,2,2,2,2,0,0,0,0,0
0,0,0,0,2,0,0,0,0,0,0,0,0,0,2,0,0,0,0
0,0,0,0,2,0,0,0,0,0,0,0,0,0,2,0,0,0,0
0,0,0,0,2,0,0,0,0,0,0,0,0,0,2,0,0,0,0
0,0,0,0,2,0,0,0,0,0,0,0,0,0,2,0,0,0,0
0,0,0,0,2,0,0,0,0,0,0,0,0,0,2,0,0,0,0
0,0,0,0,2,0,0,0,0,0,0,0,0,0,2,0,0,0,0
0,0,0,0,2,0,0,0,0,0,0,0,0,0,2,0,0,0,0
0,0,0,0,2,0,0,0,0,0,0,0,0,0,2,0,0,0,0
0,0,0,0,2,0,0,0,0,0,0,0,0,0,2,0,0,0,0
0,0,0,0,0,2,2,2,2,2,2,2,2,2,0,0,0,0,0
0,0,0,0,0,0,0,0,0,0,0,0,0,0,0,0,0,0,0
0,0,3,0,0,0,0,0,0,0,0,0,0,0,0,0,3,0,0
0,0,0,0,0,0,0,0,0,0,0,0,0,0,0,0,0,0,0
0,0,0,0,0,0,0,0,0,0,0,0,0,0,0,0,0,0,0
endlayer

layer
0,0,0,0,0,0,0,0,0,0,0,0,0,0,0,0,0,0,0
0,0,0,0,0,0,0,0,0,0,0,0,0,0,0,0,0,0,0
0,0,15,0,0,0,0,0,0,0,0,0,0,0,0,0,15,0,0
0,0,0,0,0,17,17,17,17,17,17,17,17,16,0,0,0,0,0
0,0,0,0,17,18,15,0,0,15,0,0,15,17,16,0,0,0,0
0,0,0,17,18,0,0,0,0,0,0,0,0,0,17,16,0,0,0
0,0,0,18,15,0,0,0,0,0,0,0,0,0,15,16,0,0,0
0,0,0,18,0,0,0,0,0,0,0,0,0,0,0,16,0,0,0
0,0,0,18,0,0,0,0,0,0,0,0,0,0,0,16,0,0,0
0,0,0,18,15,0,0,0,0,0,0,0,0,0,15,16,0,0,0
0,0,0,18,0,0,0,0,0,0,0,0,0,0,0,16,0,0,0
0,0,0,18,0,0,0,0,0,0,0,0,0,0,0,16,0,0,0
0,0,0,18,15,0,0,0,0,0,0,0,0,0,15,16,0,0,0
0,0,0,18,19,0,0,0,0,0,0,0,0,0,16,19,0,0,0
0,0,0,0,18,19,15,0,0,15,0,0,15,16,19,0,0,0,0
0,0,0,0,0,18,19,19,19,19,19,19,19,19,0,0,0,0,0
0,0,15,0,0,0,0,0,0,0,0,0,0,0,0,0,15,0,0
0,0,0,0,0,0,0,0,0,0,0,0,0,0,0,0,0,0,0
0,0,0,0,0,0,0,0,0,0,0,0,0,0,0,0,0,0,0
endlayer

layer
0,0,0,0,0,0,0,0,0,0,0,0,0,0,0,0,0,0,0
0,0,0,0,0,0,0,0,0,0,0,0,0,0,0,0,0,0,0
0,0,0,0,0,0,0,0,0,0,0,0,0,0,0,0,0,0,0
0,0,0,0,0,0,0,0,0,0,0,0,0,0,0,0,0,0,0
0,0,0,0,0,0,17,17,17,17,17,17,16,0,0,0,0,0,0
0,0,0,0,0,17,18,2,2,2,2,2,17,16,0,0,0,0,0
0,0,0,0,17,18,2,2,2,2,2,2,2,17,16,0,0,0,0
0,0,0,0,18,2,2,2,2,2,2,2,2,2,16,0,0,0,0
0,0,0,0,18,2,2,2,2,2,2,2,2,2,16,0,0,0,0
0,0,0,0,18,2,2,2,2,2,2,2,2,2,16,0,0,0,0
0,0,0,0,18,2,2,2,2,2,2,2,2,2,16,0,0,0,0
0,0,0,0,18,2,2,2,2,2,2,2,2,2,16,0,0,0,0
0,0,0,0,18,19,2,2,2,2,2,2,2,16,19,0,0,0,0
0,0,0,0,0,18,19,2,2,2,2,2,16,19,0,0,0,0,0
0,0,0,0,0,0,18,19,19,19,19,19,19,0,0,0,0,0,0
0,0,0,0,0,0,0,0,0,0,0,0,0,0,0,0,0,0,0
0,0,0,0,0,0,0,0,0,0,0,0,0,0,0,0,0,0,0
0,0,0,0,0,0,0,0,0,0,0,0,0,0,0,0,0,0,0
0,0,0,0,0,0,0,0,0,0,0,0,0,0,0,0,0,0,0
endlayer

