
# Created by Ruins mod version 14.4 Ingame Parser
# authoring Player: Drock1994

weight=1
embed_into_distance=0
acceptable_target_blocks=
unacceptable_target_blocks=flowing_water,water,flowing_lava,lava
dimensions=19,21,20
allowable_overhang=0
max_leveling=2
leveling_buffer=0
preserve_water=0
preserve_lava=0

rule1=0,100,BiomesOPlenty:newBopGrass-0
rule2=0,100,BiomesOPlenty:newBopDirt-0
rule3=0,100,BiomesOPlenty:newBopDirt-1
rule4=0,100,minecraft:tallgrass-1
rule5=0,100,BiomesOPlenty:foliage-11
rule6=0,100,BiomesOPlenty:foliage-2
rule7=0,100,BiomesOPlenty:foliage-10
rule8=0,100,BiomesOPlenty:logs3-2
rule9=0,100,chisel:limestone-15
rule10=0,100,BiomesOPlenty:logs3-6
rule11=0,100,BiomesOPlenty:logs3-10
rule12=2,100,minecraft:torch-1
rule13=2,100,minecraft:torch-4
rule14=2,100,minecraft:torch-3
rule15=2,100,minecraft:torch-2
rule16=0,100,chisel:fantasyblock-0
rule17=0,100,chisel:sandstone-8
rule18=0,100,ChestGenHook:dungeonChest:5-2
rule19=0,100,chisel:limestone_stairs.7-10
rule20=0,100,chisel:glass-3
rule21=0,100,BiomesOPlenty:planks-2
rule22=0,100,chisel:limestone_stairs.7-9
rule23=1,100,minecraft:torch-5
rule24=0,100,chisel:limestone_stairs.7-11
rule25=0,100,CarpentersBlocks:blockCarpentersDoor-3
rule26=0,100,CarpentersBlocks:blockCarpentersBarrier-2
rule27=0,100,chisel:limestone_stairs.7-8
rule28=0,100,chisel:limestone_slab_top-15
rule29=0,100,chisel:limestone_slab-15

layer
1,1,1,1,1,1,1,1,1,1,1,1,1,1,1,1,1,1,1,1
1,1,1,1,1,1,1,1,1,1,1,1,1,1,1,1,1,1,1,1
1,1,1,1,1,1,1,1,1,1,1,1,1,2,1,1,1,1,1,1
1,1,1,1,1,1,1,1,1,1,1,1,1,1,1,1,1,1,1,1
1,1,1,1,1,2,1,1,1,1,1,1,1,1,1,1,1,1,1,1
1,1,2,1,1,1,2,2,2,2,2,1,1,1,1,1,1,1,1,1
1,1,1,1,1,1,2,3,3,3,2,1,1,1,1,1,1,1,1,1
1,1,1,1,1,1,2,3,3,3,2,1,1,1,1,1,1,1,1,1
1,1,1,1,1,1,2,3,3,3,2,1,1,1,1,2,1,1,1,1
1,1,1,1,1,1,2,3,3,3,2,2,2,2,2,1,1,1,1,1
1,1,1,1,1,1,2,3,3,3,3,3,3,3,2,1,1,1,1,1
1,1,1,1,1,1,2,3,3,3,3,3,3,3,2,1,1,1,1,1
1,1,1,1,1,1,2,3,3,3,3,3,3,3,2,1,1,1,1,1
1,1,1,1,1,1,2,2,2,2,2,2,2,2,2,1,1,1,1,1
1,1,1,1,1,2,1,1,1,1,1,1,1,1,2,1,1,1,1,1
1,1,1,1,1,1,1,1,1,1,1,1,1,1,2,2,1,1,1,1
1,1,1,1,1,1,1,1,1,1,1,1,1,1,1,1,1,1,1,1
1,1,1,1,1,1,1,1,1,1,1,1,1,1,1,1,2,2,1,1
1,1,1,1,1,1,1,1,1,1,1,1,1,1,1,1,2,1,1,1
1,1,1,1,1,1,1,1,1,1,1,1,1,1,1,1,1,1,1,1
1,1,1,1,1,1,1,1,1,1,1,1,1,1,1,1,1,1,1,1
endlayer

layer
0,0,0,6,5,6,6,4,4,5,0,4,0,5,6,4,4,5,4,0
0,0,6,6,6,6,6,4,0,4,4,6,6,0,0,6,7,4,4,7
6,6,4,6,4,6,6,4,7,6,7,0,4,8,4,0,6,0,4,4
0,6,6,4,6,6,6,6,6,6,6,4,0,7,6,0,4,0,7,6
6,6,0,0,6,8,4,6,0,4,4,4,7,7,5,4,7,6,7,0
0,4,8,6,4,0,9,9,9,9,9,0,4,7,4,6,0,0,0,6
0,0,0,0,0,0,9,0,0,0,9,0,0,0,0,0,0,0,0,6
0,0,0,0,0,0,9,0,0,0,9,0,0,0,0,0,0,0,0,7
0,0,0,0,0,0,9,0,0,0,9,0,0,0,0,8,0,0,0,7
0,0,0,0,0,0,9,0,0,0,9,9,9,9,9,0,0,0,0,5
0,0,0,0,0,0,9,0,0,0,0,0,0,0,9,0,0,0,0,0
0,0,0,0,0,0,9,0,0,0,0,0,0,0,9,0,0,0,0,0
0,0,0,0,0,0,9,0,0,0,0,0,0,0,9,0,0,0,0,6
0,0,0,0,0,0,9,9,9,9,9,9,9,9,9,0,0,0,0,5
0,0,0,0,0,8,0,0,0,0,0,0,0,0,8,0,0,0,0,0
0,0,0,0,0,0,0,0,0,0,0,0,0,0,10,8,0,0,0,0
0,0,0,0,0,0,0,0,0,0,0,0,0,0,0,0,0,0,0,0
0,0,0,0,0,0,0,0,0,0,0,0,0,0,0,0,8,8,0,0
0,0,0,0,0,0,0,0,0,0,0,0,0,0,0,0,8,0,0,0
0,0,0,0,0,0,0,0,0,0,0,0,0,0,0,0,0,0,0,0
0,0,0,0,0,0,0,0,0,0,0,0,0,0,0,0,0,0,0,0
endlayer

layer
0,0,0,0,0,0,0,0,0,0,0,0,0,0,0,0,0,0,0,0
0,0,0,0,0,0,0,0,0,0,0,0,0,0,0,0,0,0,0,0
0,0,0,0,0,0,0,0,0,0,0,0,0,8,0,0,0,0,0,0
0,0,0,0,0,0,0,0,0,0,0,0,0,10,0,0,0,0,0,0
0,0,0,0,0,8,0,0,0,0,0,0,0,10,0,0,0,0,0,0
0,11,8,0,0,0,9,9,9,9,9,0,0,0,0,0,0,0,0,0
0,0,0,0,0,0,9,0,12,0,9,0,0,0,0,0,0,0,0,0
0,0,0,0,0,0,9,0,0,0,9,0,0,0,0,0,0,0,0,0
0,0,0,0,0,0,9,0,0,0,9,0,0,0,0,8,0,0,0,0
0,0,0,0,0,0,9,0,0,0,9,9,9,9,9,0,0,0,0,0
0,0,0,0,0,0,9,13,0,0,0,0,0,0,9,0,0,0,0,0
0,0,0,0,0,0,9,0,0,0,0,0,0,14,9,0,0,0,0,0
0,0,0,0,0,0,9,0,0,15,0,0,0,0,9,0,0,0,0,0
0,0,0,0,0,0,9,9,9,9,9,9,9,9,9,0,0,0,0,0
0,0,0,0,0,8,0,0,0,0,0,0,0,0,8,0,0,0,0,0
0,0,0,0,0,0,0,0,0,0,0,0,0,11,8,0,0,0,0,0
0,0,0,0,0,0,0,0,0,0,0,0,0,0,0,0,0,0,0,0
0,0,0,0,0,0,0,0,0,0,0,0,0,0,0,0,8,11,0,0
0,0,0,0,0,0,0,0,0,0,0,0,0,0,0,0,10,11,0,0
0,0,0,0,0,0,0,0,0,0,0,0,0,0,0,0,0,0,0,0
0,0,0,0,0,0,0,0,0,0,0,0,0,0,0,0,0,0,0,0
endlayer

layer
0,0,0,0,0,0,0,0,0,0,0,0,0,0,0,0,0,0,0,0
0,0,0,0,0,0,0,0,0,0,0,0,0,10,0,0,0,0,0,0
0,0,0,0,0,0,0,0,0,0,0,0,0,8,11,11,0,0,0,0
0,0,0,0,0,0,0,0,0,0,0,0,0,0,0,0,0,0,0,0
0,0,8,0,0,8,0,0,0,0,0,0,0,0,0,0,0,0,0,0
0,0,8,11,0,0,9,9,9,9,9,0,0,0,0,0,0,0,0,0
0,0,10,0,0,0,9,0,0,0,9,0,0,0,0,0,0,0,0,0
0,0,10,0,0,0,9,0,0,0,9,0,0,0,0,0,0,0,0,0
0,0,0,0,0,0,9,0,0,0,9,0,0,0,0,8,0,0,0,0
0,0,0,0,0,0,9,0,0,0,9,9,9,9,9,0,0,0,0,0
0,0,0,0,0,0,9,0,0,0,0,0,0,0,9,0,0,0,0,0
0,0,0,0,0,0,9,0,0,0,0,0,0,0,9,0,0,0,0,0
0,0,0,0,0,0,9,0,0,0,0,0,0,0,9,0,0,0,0,0
0,0,0,0,0,0,9,9,9,9,9,9,9,9,9,0,0,0,0,0
0,0,0,0,0,8,0,0,0,0,0,0,0,11,8,0,0,0,0,0
0,0,0,0,0,0,0,0,0,0,0,0,0,10,8,0,0,0,0,0
0,0,0,0,0,0,0,0,0,0,0,0,0,10,0,0,0,0,0,0
0,0,0,0,0,0,0,0,0,0,0,0,0,0,0,0,8,11,0,0
0,0,0,0,0,0,0,0,0,0,0,0,0,0,0,0,10,0,0,0
0,0,0,0,0,0,0,0,0,0,0,0,0,0,0,0,10,0,0,0
0,0,0,0,0,0,0,0,0,0,0,0,0,0,0,0,0,0,0,0
endlayer

layer
0,0,0,0,0,0,0,0,0,0,0,0,0,0,0,0,0,0,0,0
0,0,0,0,0,0,0,0,0,0,0,0,0,0,0,0,0,0,0,0
0,0,0,0,0,0,0,0,0,0,0,0,0,8,11,0,0,0,0,0
0,0,10,0,0,0,0,0,0,0,0,0,0,10,0,0,0,0,0,0
0,0,0,0,0,8,8,8,8,8,8,8,0,0,0,0,0,0,0,0
11,11,8,11,0,8,16,16,16,16,16,8,0,0,0,0,0,0,0,0
0,0,0,0,0,8,16,16,16,16,16,8,0,0,0,0,0,0,0,0
0,0,0,0,0,8,16,16,16,16,16,8,0,0,0,0,0,0,0,0
0,0,0,0,0,8,16,16,16,16,16,10,8,8,8,8,0,0,0,0
0,0,0,0,0,8,16,16,16,16,16,16,16,16,16,8,0,0,0,0
0,0,0,0,0,8,16,16,16,16,16,16,16,16,16,8,0,0,0,0
0,0,0,0,0,8,16,16,16,16,16,16,16,16,16,8,0,0,0,0
0,0,0,0,0,8,16,16,16,16,16,16,16,16,16,8,0,0,0,0
0,0,0,0,0,8,16,16,16,16,16,16,16,16,16,8,0,0,0,0
0,0,0,0,0,8,8,8,8,8,8,8,8,8,8,8,0,0,0,0
0,0,0,0,0,0,0,0,0,0,0,0,0,8,8,0,0,0,0,0
0,0,0,0,0,0,0,0,0,0,0,0,0,0,10,0,0,0,0,0
0,0,0,0,0,0,0,0,0,0,0,0,0,0,0,0,8,11,11,0
0,0,0,0,0,0,0,0,0,0,0,0,0,0,0,0,10,11,0,0
0,0,0,0,0,0,0,0,0,0,0,0,0,0,0,0,0,0,0,0
0,0,0,0,0,0,0,0,0,0,0,0,0,0,0,0,0,0,0,0
endlayer

layer
0,0,0,0,0,0,0,0,0,0,0,0,0,10,0,0,0,0,0,0
0,0,0,0,0,0,0,0,0,0,0,0,0,10,0,0,0,0,0,0
0,0,0,0,0,0,0,0,0,0,0,0,0,8,0,0,0,0,0,0
0,0,0,0,0,0,0,0,0,0,0,0,0,0,0,0,0,0,0,0
0,0,0,0,11,8,17,17,17,17,17,8,0,0,0,0,0,0,0,0
0,0,8,0,11,10,0,0,0,0,0,17,0,0,0,0,0,0,0,0
0,0,10,0,11,10,0,0,0,0,0,17,0,0,0,0,0,0,0,0
0,0,0,0,11,10,0,0,0,0,0,17,0,0,0,0,0,0,0,0
0,0,0,0,11,10,18,0,0,0,0,8,17,17,17,8,0,0,0,0
0,0,0,0,11,10,18,0,0,0,0,0,0,0,0,17,0,0,0,0
0,0,0,0,11,10,0,0,0,0,0,0,0,0,0,17,0,0,0,0
0,0,0,0,11,10,0,0,0,0,0,0,0,0,0,17,0,0,0,0
0,0,0,0,11,10,0,0,0,0,0,0,0,0,0,17,0,0,0,0
0,0,0,0,11,10,9,9,19,0,0,0,0,0,0,17,0,0,0,0
0,0,0,0,11,8,17,17,17,17,17,17,17,17,17,8,0,0,0,0
0,0,0,0,0,0,0,0,0,0,0,0,0,8,8,0,0,0,0,0
0,0,0,0,0,0,0,0,0,0,0,0,0,10,0,0,0,0,0,0
0,0,0,0,0,0,0,0,0,0,0,0,0,0,0,0,0,0,0,0
0,0,0,0,0,0,0,0,0,0,0,0,0,0,0,0,0,0,0,0
0,0,0,0,0,0,0,0,0,0,0,0,0,0,0,0,0,0,0,0
0,0,0,0,0,0,0,0,0,0,0,0,0,0,0,0,0,0,0,0
endlayer

layer
0,0,0,0,0,0,0,0,0,0,0,0,0,0,0,0,0,0,0,0
0,0,0,0,0,0,0,0,0,0,0,0,0,0,0,0,0,0,0,0
0,0,0,0,0,0,0,0,0,0,0,0,0,8,0,0,0,0,0,0
0,0,0,0,0,0,0,0,0,0,0,0,0,0,0,0,0,0,0,0
0,0,8,0,11,8,17,20,20,20,17,8,0,0,0,0,0,0,0,0
0,8,8,0,0,17,12,0,0,0,12,17,0,0,0,0,0,0,0,0
11,11,8,0,0,17,0,0,0,0,0,20,0,0,0,0,0,0,0,0
0,0,10,0,0,17,0,0,0,0,0,17,0,0,0,0,0,0,0,0
0,0,10,0,0,17,13,0,0,0,0,8,17,20,17,8,0,0,0,0
0,0,0,0,0,17,0,0,0,0,0,0,0,0,14,17,0,0,0,0
0,0,0,0,0,17,13,0,0,0,0,0,0,0,0,20,0,0,0,0
0,0,0,0,0,17,0,0,0,0,0,0,0,0,0,20,0,0,0,0
0,0,0,0,0,17,0,0,0,0,0,0,0,0,0,20,0,0,0,0
0,0,0,0,0,17,9,19,0,0,0,0,0,0,14,17,0,0,0,0
0,0,0,0,11,8,17,17,17,17,17,17,17,17,17,8,0,0,0,0
0,0,0,0,0,0,0,0,0,0,0,0,0,8,8,0,0,0,0,0
0,0,0,0,0,0,0,0,0,0,0,0,11,11,10,0,0,0,0,0
0,0,0,0,0,0,0,0,0,0,0,0,0,0,10,0,0,0,0,0
0,0,0,0,0,0,0,0,0,0,0,0,0,0,0,0,0,0,0,0
0,0,0,0,0,0,0,0,0,0,0,0,0,0,0,0,0,0,0,0
0,0,0,0,0,0,0,0,0,0,0,0,0,0,0,0,0,0,0,0
endlayer

layer
0,0,0,0,0,0,0,0,0,0,0,0,0,10,0,0,0,0,0,0
0,0,0,0,0,0,0,0,0,0,0,0,0,10,0,0,0,0,0,0
0,0,0,0,0,0,0,0,0,0,0,0,0,8,11,11,0,0,0,0
0,0,10,0,0,0,0,0,0,0,0,0,0,10,0,0,0,0,0,0
0,0,0,0,11,8,17,17,17,17,17,8,0,10,0,0,0,0,0,0
0,8,8,0,0,17,0,0,0,0,0,17,0,0,0,0,0,0,0,0
0,10,10,0,0,17,0,0,0,0,0,17,0,0,0,0,0,0,0,0
0,0,10,0,0,17,0,0,0,0,0,17,0,0,0,0,0,0,0,0
0,0,0,0,0,17,0,0,0,0,0,8,17,17,17,8,0,0,0,0
0,0,0,0,0,17,0,0,0,0,0,0,0,0,0,17,0,0,0,0
0,0,0,0,0,17,0,0,0,0,0,0,0,0,0,17,0,0,0,0
0,0,0,0,0,17,0,0,0,0,0,0,0,0,0,17,0,0,0,0
0,0,0,0,0,17,0,0,0,0,0,0,0,0,0,17,0,0,0,0
0,0,0,0,0,17,19,0,0,0,0,0,0,0,0,17,0,0,0,0
0,0,0,0,11,8,17,17,20,17,17,20,17,17,17,8,0,0,0,0
0,0,0,0,0,0,0,0,0,0,0,0,0,0,8,10,0,0,0,0
0,0,0,0,0,0,0,0,0,0,0,0,0,0,8,10,0,0,0,0
0,0,0,0,0,0,0,0,0,0,0,0,0,0,0,0,0,0,0,0
0,0,0,0,0,0,0,0,0,0,0,0,0,0,0,0,0,0,0,0
0,0,0,0,0,0,0,0,0,0,0,0,0,0,0,0,0,0,0,0
0,0,0,0,0,0,0,0,0,0,0,0,0,0,0,0,0,0,0,0
endlayer

layer
0,0,0,0,0,0,0,0,0,0,0,0,0,8,11,0,0,0,0,0
0,0,0,0,0,0,0,0,0,0,0,0,0,10,0,0,0,0,0,0
0,0,0,0,10,0,0,0,0,0,0,0,10,8,11,0,0,0,0,0
0,0,0,0,8,8,8,8,8,8,8,8,8,0,0,0,0,0,0,0
0,0,0,0,10,21,0,0,0,0,0,8,8,0,0,0,0,0,0,0
11,0,8,0,10,21,0,0,0,0,0,8,8,0,0,0,0,0,0,0
0,0,10,11,10,21,0,0,0,0,0,8,8,0,0,0,0,0,0,0
0,0,0,0,10,21,0,0,0,0,0,8,8,8,8,8,0,0,0,0
0,0,0,0,10,21,0,0,0,0,0,8,11,8,8,8,0,0,0,0
0,0,0,0,10,21,0,0,0,0,0,0,0,0,0,8,0,0,0,0
0,0,0,0,10,21,0,0,0,0,0,0,0,0,0,8,0,0,0,0
0,0,0,0,10,21,0,0,0,0,0,0,0,0,0,8,0,0,0,0
0,0,0,0,10,21,22,0,0,0,0,0,0,0,0,8,0,0,0,0
0,0,0,0,10,21,0,0,0,0,0,0,0,0,0,8,0,0,0,0
0,0,0,11,10,10,17,17,20,17,17,20,17,17,17,8,0,0,0,0
0,0,0,0,10,0,0,0,0,0,0,0,0,0,8,8,0,0,0,0
0,0,0,0,10,0,0,0,0,0,0,0,0,0,8,8,0,0,0,0
0,0,0,0,0,0,0,0,0,0,0,0,0,0,10,0,0,0,0,0
0,0,0,0,0,0,0,0,0,0,0,0,0,0,0,0,0,0,0,0
0,0,0,0,0,0,0,0,0,0,0,0,0,0,0,0,0,0,0,0
0,0,0,0,0,0,0,0,0,0,0,0,0,0,0,0,0,0,0,0
endlayer

layer
0,0,0,0,0,0,0,0,0,0,0,0,0,23,0,0,0,0,0,0
0,0,0,0,0,0,0,0,0,0,0,0,0,10,0,0,0,0,0,0
0,0,0,0,10,0,0,0,0,0,0,0,10,8,0,0,0,0,0,0
0,0,0,0,8,8,17,17,17,17,17,8,8,0,0,0,0,0,0,0
0,0,0,0,0,21,9,9,9,9,9,21,0,0,0,0,0,0,0,0
0,0,8,0,0,21,9,9,9,9,9,21,0,0,0,0,0,0,0,0
0,0,0,0,0,21,9,9,9,9,9,21,0,0,0,0,0,0,0,0
0,0,0,0,0,21,9,9,9,9,9,21,8,0,0,8,0,0,0,0
0,0,0,0,24,21,9,9,9,9,9,8,21,21,21,8,0,0,0,0
0,0,0,0,24,21,9,9,9,9,9,9,9,9,21,0,0,0,0,0
0,0,0,0,0,21,9,9,9,9,9,9,9,9,21,0,0,0,0,0
0,0,0,0,0,21,22,0,0,0,0,0,0,0,21,0,0,0,0,0
0,0,0,0,0,21,0,0,0,0,0,0,0,0,21,0,0,0,0,0
0,0,0,0,0,21,0,0,0,0,0,0,0,0,21,0,0,0,0,0
0,0,0,0,8,8,17,17,20,17,17,20,17,17,21,0,0,0,0,0
0,0,0,11,8,11,0,0,0,0,0,0,0,0,8,8,0,0,0,0
0,0,0,0,0,0,0,0,0,0,0,0,0,11,8,8,0,0,0,0
0,0,0,0,0,0,0,0,0,0,0,0,0,0,0,0,0,0,0,0
0,0,0,0,0,0,0,0,0,0,0,0,0,0,0,0,0,0,0,0
0,0,0,0,0,0,0,0,0,0,0,0,0,0,0,0,0,0,0,0
0,0,0,0,0,0,0,0,0,0,0,0,0,0,0,0,0,0,0,0
endlayer

layer
0,0,0,0,0,0,0,0,0,0,0,0,0,0,0,0,0,0,0,0
0,0,0,0,0,0,0,0,0,0,0,0,0,0,0,0,0,0,0,0
0,0,0,0,10,0,0,0,0,0,0,0,10,8,0,0,0,0,0,0
0,0,0,0,8,8,17,17,20,17,17,8,8,0,0,0,0,0,0,0
0,0,0,0,0,21,0,0,0,0,0,21,0,0,0,0,0,0,0,0
0,0,23,0,0,21,0,0,0,0,0,21,0,0,0,0,0,0,0,0
0,0,0,0,0,21,0,0,0,0,0,21,0,0,0,10,0,0,0,0
0,0,0,0,0,20,0,0,0,0,0,21,8,0,0,8,11,0,0,0
0,0,0,0,0,25,0,0,0,0,0,8,21,21,21,8,0,0,0,0
0,0,0,0,0,25,0,0,0,0,0,0,0,0,21,0,0,0,0,0
0,0,0,0,0,20,0,26,26,26,26,26,26,26,21,0,0,0,0,0
0,0,0,0,0,21,0,0,0,0,0,0,0,0,21,0,0,0,0,0
0,0,0,0,0,21,0,0,0,0,0,0,0,0,21,0,0,0,0,0
0,0,0,0,0,21,0,0,0,0,0,0,0,0,21,0,0,0,0,0
0,0,0,0,8,8,17,17,20,17,17,20,17,17,21,0,0,0,0,0
0,0,0,23,8,0,0,0,0,0,0,0,0,0,8,8,0,0,0,0
0,0,0,0,0,0,0,0,0,0,0,0,0,0,8,10,11,0,0,0
0,0,0,0,0,0,0,0,0,0,0,0,0,0,10,10,0,0,0,0
0,0,0,0,0,0,0,0,0,0,0,0,0,0,10,0,0,0,0,0
0,0,0,0,0,0,0,0,0,0,0,0,0,0,0,0,0,0,0,0
0,0,0,0,0,0,0,0,0,0,0,0,0,0,0,0,0,0,0,0
endlayer

layer
0,0,0,0,0,0,0,0,0,0,0,0,0,0,0,0,0,0,0,0
0,0,0,0,0,0,0,0,0,0,0,0,0,0,0,0,0,0,0,0
0,0,0,0,10,0,0,0,0,0,0,0,10,8,0,0,0,0,0,0
0,0,0,0,8,8,17,17,20,17,17,8,8,0,0,0,0,0,0,0
0,0,0,0,0,21,0,0,0,0,0,21,0,0,0,0,0,0,0,0
0,0,0,0,0,21,0,0,0,0,0,21,0,0,0,0,0,0,0,0
0,0,0,0,0,21,13,0,0,0,14,21,0,0,0,0,0,0,0,0
0,0,0,0,0,20,0,0,0,0,0,21,8,0,0,8,23,0,0,0
0,0,0,0,0,25,0,0,0,0,0,8,21,21,21,8,0,0,0,0
0,0,0,0,0,25,0,0,0,0,0,0,0,0,21,0,0,0,0,0
0,0,0,0,0,20,0,0,0,0,0,0,0,0,21,0,0,0,0,0
0,0,0,0,0,21,13,0,0,0,0,0,0,0,21,0,0,0,0,0
0,0,0,0,0,21,0,0,0,0,0,0,0,0,21,0,0,0,0,0
0,0,0,0,0,21,0,0,0,0,0,0,0,0,21,0,0,0,0,0
0,0,0,0,8,8,17,17,20,17,17,20,17,17,21,0,0,0,0,0
0,0,0,0,8,0,0,0,0,0,0,0,0,0,8,8,0,0,0,0
0,0,0,0,0,0,0,0,0,0,0,0,0,11,8,8,23,0,0,0
0,0,0,0,0,0,0,0,0,0,0,0,0,0,0,0,0,0,0,0
0,0,0,0,0,0,0,0,0,0,0,0,0,0,8,0,0,0,0,0
0,0,0,0,0,0,0,0,0,0,0,0,0,0,0,0,0,0,0,0
0,0,0,0,0,0,0,0,0,0,0,0,0,0,0,0,0,0,0,0
endlayer

layer
0,0,0,0,0,0,0,0,0,0,0,0,0,0,0,0,0,0,0,0
0,0,0,0,0,0,0,0,0,0,0,0,0,0,0,0,0,0,0,0
0,0,0,0,10,0,0,0,0,0,0,0,10,8,0,0,0,0,0,0
0,0,0,0,8,8,17,17,20,17,17,8,8,0,0,0,0,0,0,0
0,0,0,0,0,21,0,0,0,0,0,21,10,0,0,0,0,0,0,0
0,0,0,0,0,21,0,0,0,0,0,21,10,0,0,0,0,0,0,0
0,0,0,0,0,21,0,0,0,0,0,21,10,0,0,0,0,0,0,0
0,0,0,0,0,21,0,0,0,0,0,21,10,11,11,8,0,0,0,0
0,0,0,0,0,21,0,0,0,0,0,8,11,11,11,10,0,0,0,0
0,0,0,0,0,21,0,0,0,0,0,0,0,0,0,10,0,0,0,0
0,0,0,0,0,21,0,0,0,0,0,0,0,0,23,10,0,0,0,0
0,0,0,0,0,21,0,0,0,0,0,0,0,0,0,10,0,0,0,0
0,0,0,0,0,21,0,0,0,0,0,0,0,0,23,10,0,0,0,0
0,0,0,0,0,21,0,0,15,0,0,15,0,0,0,10,0,0,0,0
0,0,0,0,8,8,17,17,17,17,17,17,17,17,8,10,0,0,0,0
0,0,0,0,8,0,0,0,0,0,0,0,0,0,8,8,0,0,0,0
0,0,0,0,0,0,0,0,0,0,0,0,0,0,8,8,0,0,0,0
0,0,0,0,0,0,0,0,0,0,0,0,0,0,0,0,0,0,0,0
0,0,0,0,0,0,0,0,0,0,0,0,0,0,0,0,0,0,0,0
0,0,0,0,0,0,0,0,0,0,0,0,0,0,0,0,0,0,0,0
0,0,0,0,0,0,0,0,0,0,0,0,0,0,0,0,0,0,0,0
endlayer

layer
0,0,0,0,0,0,0,0,0,0,0,0,0,0,0,0,0,0,0,0
0,0,0,24,0,0,0,0,0,0,0,0,0,19,0,0,0,0,0,0
0,0,0,24,10,0,0,0,0,0,0,0,10,19,0,0,0,0,0,0
0,0,0,24,8,8,17,17,17,17,17,8,8,19,0,0,0,0,0,0
0,0,0,24,10,21,0,0,0,0,0,21,21,19,0,0,0,0,0,0
0,0,0,24,10,21,0,0,0,0,0,21,21,19,0,0,0,0,0,0
0,0,0,24,10,21,0,0,0,0,0,21,21,19,0,0,0,0,0,0
0,0,0,24,10,21,0,0,0,0,0,21,21,27,27,27,27,0,0,0
0,0,0,24,10,21,0,0,0,0,0,21,21,21,21,8,0,0,0,0
0,0,0,24,10,21,0,0,0,0,0,0,0,0,21,8,0,0,0,0
0,0,0,24,10,21,0,0,0,0,0,0,0,0,21,8,0,0,0,0
0,0,0,24,10,21,0,0,0,0,0,0,0,0,21,8,0,0,0,0
0,0,0,24,10,21,0,0,0,0,0,0,0,0,21,8,0,0,0,0
0,0,0,24,10,21,0,0,0,0,0,0,0,0,21,8,0,0,0,0
0,0,0,24,10,8,17,17,17,17,17,17,17,17,8,8,0,0,0,0
0,0,0,24,11,10,10,10,10,10,10,10,10,10,10,10,0,0,0,0
0,0,0,24,22,22,22,22,22,22,22,22,22,22,22,22,22,0,0,0
0,0,0,0,0,0,0,0,0,0,0,0,0,0,0,0,0,0,0,0
0,0,0,0,0,0,0,0,0,0,0,0,0,0,0,0,0,0,0,0
0,0,0,0,0,0,0,0,0,0,0,0,0,0,0,0,0,0,0,0
0,0,0,0,0,0,0,0,0,0,0,0,0,0,0,0,0,0,0,0
endlayer

layer
0,0,0,0,0,0,0,0,0,0,0,0,0,0,0,0,0,0,0,0
0,0,0,0,24,0,0,0,0,0,0,0,19,0,0,0,0,0,0,0
0,0,0,0,24,10,0,0,0,0,0,10,19,0,0,0,0,0,0,0
0,0,0,0,24,8,8,8,8,8,8,8,19,0,0,0,0,0,0,0
0,0,0,0,24,21,0,0,0,0,0,21,19,0,0,0,0,0,0,0
0,0,0,0,24,21,0,0,0,0,0,21,19,0,0,0,0,0,0,0
0,0,0,0,24,21,0,0,0,0,0,21,19,0,0,0,0,0,0,0
0,0,0,0,24,21,0,0,0,0,0,21,19,0,0,0,0,0,0,0
0,0,0,0,24,21,0,0,0,0,0,21,27,27,27,27,27,0,0,0
0,0,0,0,24,21,0,0,0,0,0,0,0,0,0,8,0,0,0,0
0,0,0,0,24,21,0,0,0,0,0,0,0,0,23,8,0,0,0,0
0,0,0,0,24,21,0,0,0,0,0,0,0,0,0,8,0,0,0,0
0,0,0,0,24,21,0,0,0,0,0,0,0,0,23,8,0,0,0,0
0,0,0,0,24,21,0,0,0,0,0,0,0,0,0,8,0,0,0,0
0,0,0,0,24,8,8,8,8,8,8,8,8,8,8,8,0,0,0,0
0,0,0,0,22,22,22,22,22,22,22,22,22,22,22,22,22,0,0,0
0,0,0,0,0,0,0,0,0,0,0,0,0,0,0,0,0,0,0,0
0,0,0,0,0,0,0,0,0,0,0,0,0,0,0,0,0,0,0,0
0,0,0,0,0,0,0,0,0,0,0,0,0,0,0,0,0,0,0,0
0,0,0,0,0,0,0,0,0,0,0,0,0,0,0,0,0,0,0,0
0,0,0,0,0,0,0,0,0,0,0,0,0,0,0,0,0,0,0,0
endlayer

layer
0,0,0,0,0,0,0,0,0,0,0,0,0,0,0,0,0,0,0,0
0,0,0,0,0,24,0,0,0,0,0,19,0,0,0,0,0,0,0,0
0,0,0,0,0,24,10,0,0,0,10,19,0,0,0,0,0,0,0,0
0,0,0,0,0,24,8,8,8,8,8,19,0,0,0,0,0,0,0,0
0,0,0,0,0,24,0,0,0,0,0,19,0,0,0,0,0,0,0,0
0,0,0,0,0,24,0,0,0,0,0,19,0,0,0,0,0,0,0,0
0,0,0,0,0,24,0,0,0,0,0,19,0,0,0,0,0,0,0,0
0,0,0,0,0,24,0,0,0,0,0,19,0,0,0,0,0,0,0,0
0,0,0,0,0,24,0,0,0,0,0,19,0,0,0,0,0,0,0,0
0,0,0,0,0,24,0,0,0,0,0,27,27,27,27,27,27,0,0,0
0,0,0,0,0,24,0,0,0,0,0,0,0,0,0,8,0,0,0,0
0,0,0,0,0,24,0,0,0,0,0,0,0,0,0,8,0,0,0,0
0,0,0,0,0,24,0,0,0,0,0,0,0,0,0,8,0,0,0,0
0,0,0,0,0,24,0,0,0,0,0,0,0,0,0,8,0,0,0,0
0,0,0,0,0,22,22,22,22,22,22,22,22,22,22,22,22,0,0,0
0,0,0,0,0,0,0,0,0,0,0,0,0,0,0,0,0,0,0,0
0,0,0,0,0,0,0,0,0,0,0,0,0,0,0,0,0,0,0,0
0,0,0,0,0,0,0,0,0,0,0,0,0,0,0,0,0,0,0,0
0,0,0,0,0,0,0,0,0,0,0,0,0,0,0,0,0,0,0,0
0,0,0,0,0,0,0,0,0,0,0,0,0,0,0,0,0,0,0,0
0,0,0,0,0,0,0,0,0,0,0,0,0,0,0,0,0,0,0,0
endlayer

layer
0,0,0,0,0,0,0,0,0,0,0,0,0,0,0,0,0,0,0,0
0,0,0,0,0,0,24,0,0,0,19,0,0,0,0,0,0,0,0,0
0,0,0,0,0,0,24,10,0,10,19,0,0,0,0,0,0,0,0,0
0,0,0,0,0,0,24,8,8,8,19,0,0,0,0,0,0,0,0,0
0,0,0,0,0,0,24,0,0,0,19,0,0,0,0,0,0,0,0,0
0,0,0,0,0,0,24,0,0,0,19,0,0,0,0,0,0,0,0,0
0,0,0,0,0,0,24,0,0,0,19,0,0,0,0,0,0,0,0,0
0,0,0,0,0,0,24,0,0,0,19,0,0,0,0,0,0,0,0,0
0,0,0,0,0,0,24,0,0,0,19,0,0,0,0,0,0,0,0,0
0,0,0,0,0,0,24,0,0,0,19,0,0,0,0,0,0,0,0,0
0,0,0,0,0,0,24,0,0,0,27,27,27,27,27,27,27,0,0,0
0,0,0,0,0,0,24,0,0,0,0,0,0,0,0,8,28,0,0,0
0,0,0,0,0,0,24,0,0,0,0,0,0,0,0,8,28,0,0,0
0,0,0,0,0,0,22,22,22,22,22,22,22,22,22,22,22,0,0,0
0,0,0,0,0,0,0,0,0,0,0,0,0,0,0,0,0,0,0,0
0,0,0,0,0,0,0,0,0,0,0,0,0,0,0,0,0,0,0,0
0,0,0,0,0,0,0,0,0,0,0,0,0,0,0,0,0,0,0,0
0,0,0,0,0,0,0,0,0,0,0,0,0,0,0,0,0,0,0,0
0,0,0,0,0,0,0,0,0,0,0,0,0,0,0,0,0,0,0,0
0,0,0,0,0,0,0,0,0,0,0,0,0,0,0,0,0,0,0,0
0,0,0,0,0,0,0,0,0,0,0,0,0,0,0,0,0,0,0,0
endlayer

layer
0,0,0,0,0,0,0,0,0,0,0,0,0,0,0,0,0,0,0,0
0,0,0,0,0,0,0,24,9,19,0,0,0,0,0,0,0,0,0,0
0,0,0,0,0,0,0,24,10,19,0,0,0,0,0,0,0,0,0,0
0,0,0,0,0,0,0,24,8,19,0,0,0,0,0,0,0,0,0,0
0,0,0,0,0,0,0,24,10,19,0,0,0,0,0,0,0,0,0,0
0,0,0,0,0,0,0,24,10,19,0,0,0,0,0,0,0,0,0,0
0,0,0,0,0,0,0,24,10,19,0,0,0,0,0,0,0,0,0,0
0,0,0,0,0,0,0,24,10,19,0,0,0,0,0,0,0,0,0,0
0,0,0,0,0,0,0,24,10,19,0,0,0,0,0,0,0,0,0,0
0,0,0,0,0,0,0,24,10,19,0,0,0,0,0,0,0,0,0,0
0,0,0,0,0,0,0,24,10,19,0,0,0,0,0,0,0,0,0,0
0,0,0,0,0,0,0,24,10,27,27,27,27,27,27,27,29,0,0,0
0,0,0,0,0,0,0,24,22,22,22,22,22,22,22,22,29,0,0,0
0,0,0,0,0,0,0,0,0,0,0,0,0,0,0,0,0,0,0,0
0,0,0,0,0,0,0,0,0,0,0,0,0,0,0,0,0,0,0,0
0,0,0,0,0,0,0,0,0,0,0,0,0,0,0,0,0,0,0,0
0,0,0,0,0,0,0,0,0,0,0,0,0,0,0,0,0,0,0,0
0,0,0,0,0,0,0,0,0,0,0,0,0,0,0,0,0,0,0,0
0,0,0,0,0,0,0,0,0,0,0,0,0,0,0,0,0,0,0,0
0,0,0,0,0,0,0,0,0,0,0,0,0,0,0,0,0,0,0,0
0,0,0,0,0,0,0,0,0,0,0,0,0,0,0,0,0,0,0,0
endlayer

layer
0,0,0,0,0,0,0,0,0,0,0,0,0,0,0,0,0,0,0,0
0,0,0,0,0,0,0,0,0,0,0,0,0,0,0,0,0,0,0,0
0,0,0,0,0,0,0,0,29,0,0,0,0,0,0,0,0,0,0,0
0,0,0,0,0,0,0,0,29,0,0,0,0,0,0,0,0,0,0,0
0,0,0,0,0,0,0,0,29,0,0,0,0,0,0,0,0,0,0,0
0,0,0,0,0,0,0,0,29,0,0,0,0,0,0,0,0,0,0,0
0,0,0,0,0,0,0,0,29,0,0,0,0,0,0,0,0,0,0,0
0,0,0,0,0,0,0,0,29,0,0,0,0,0,0,0,0,0,0,0
0,0,0,0,0,0,0,0,29,0,0,0,0,0,0,0,0,0,0,0
0,0,0,0,0,0,0,0,29,0,0,0,0,0,0,0,0,0,0,0
0,0,0,0,0,0,0,0,29,0,0,0,0,0,0,0,0,0,0,0
0,0,0,0,0,0,0,0,29,0,0,0,0,0,0,0,0,0,0,0
0,0,0,0,0,0,0,0,0,0,0,0,0,0,0,0,0,0,0,0
0,0,0,0,0,0,0,0,0,0,0,0,0,0,0,0,0,0,0,0
0,0,0,0,0,0,0,0,0,0,0,0,0,0,0,0,0,0,0,0
0,0,0,0,0,0,0,0,0,0,0,0,0,0,0,0,0,0,0,0
0,0,0,0,0,0,0,0,0,0,0,0,0,0,0,0,0,0,0,0
0,0,0,0,0,0,0,0,0,0,0,0,0,0,0,0,0,0,0,0
0,0,0,0,0,0,0,0,0,0,0,0,0,0,0,0,0,0,0,0
0,0,0,0,0,0,0,0,0,0,0,0,0,0,0,0,0,0,0,0
0,0,0,0,0,0,0,0,0,0,0,0,0,0,0,0,0,0,0,0
endlayer

