
# Created by Ruins mod version 14.4 Ingame Parser
# authoring Player: Drock1994

weight=1
embed_into_distance=0
acceptable_target_blocks=
unacceptable_target_blocks=flowing_water,water,flowing_lava,lava
dimensions=12,8,13
allowable_overhang=0
max_leveling=2
leveling_buffer=0
preserve_water=0
preserve_lava=0

rule1=0,100,minecraft:grass-0
rule2=0,100,minecraft:dirt-0
rule3=0,100,minecraft:planks-0
rule4=0,100,minecraft:log-1
rule5=0,100,MineFactoryReloaded:stone-1
rule6=0,100,minecraft:wooden_door-0
rule7=0,100,minecraft:ladder-2
rule8=0,100,minecraft:glass_pane-0
rule9=0,100,minecraft:wooden_door-8
rule10=0,100,minecraft:wooden_door-9
rule11=2,100,minecraft:torch-4
rule12=0,100,minecraft:stone_brick_stairs-0
rule13=0,100,minecraft:log-9
rule14=0,100,minecraft:log-5
rule15=0,100,minecraft:stone_brick_stairs-1
rule16=2,100,minecraft:torch-3
rule17=0,100,ChestGenHook:dungeonChest:5-3

layer
1,1,1,1,1,1,1,1,1,1,1,1,1
1,2,2,3,3,2,2,2,2,2,2,2,1
1,2,3,3,3,3,3,3,3,3,3,2,1
1,2,3,3,3,3,3,3,3,3,3,2,1
1,2,3,3,3,3,3,3,3,3,3,2,1
1,2,3,3,3,3,3,3,3,3,3,2,1
1,2,2,2,2,2,2,2,2,2,2,2,1
1,1,1,1,1,1,1,1,1,1,1,1,1
endlayer

layer
0,0,0,0,0,0,0,0,0,0,0,0,0
0,4,5,6,6,5,4,5,5,5,5,4,0
0,5,0,0,0,0,0,0,0,0,0,5,0
0,5,0,0,0,0,0,0,0,0,0,5,0
0,5,0,0,0,0,0,0,0,0,0,5,0
0,5,7,0,0,0,0,0,0,0,0,5,0
0,4,5,5,5,5,4,5,5,5,5,4,0
0,0,0,0,0,0,0,0,0,0,0,0,0
endlayer

layer
0,0,0,0,0,0,0,0,0,0,0,0,0
0,4,5,10,9,5,4,5,8,8,5,4,0
0,5,0,0,0,0,0,0,0,0,0,5,0
0,8,0,0,0,0,0,0,0,0,0,8,0
0,8,0,0,0,0,0,0,0,0,0,8,0
0,5,7,0,0,0,0,0,0,0,0,5,0
0,4,5,8,8,5,4,5,8,8,5,4,0
0,0,0,0,0,0,0,0,0,0,0,0,0
endlayer

layer
0,0,0,0,0,0,0,0,0,0,0,0,0
0,4,5,5,5,5,4,5,5,5,5,4,0
0,5,0,0,0,0,0,0,0,0,0,5,0
0,5,11,0,0,0,0,0,0,0,0,5,0
0,5,11,0,0,0,0,0,0,0,0,5,0
0,5,7,0,0,0,0,0,0,0,0,5,0
0,4,5,5,5,5,4,5,5,5,5,4,0
0,0,0,0,0,0,0,0,0,0,0,0,0
endlayer

layer
0,0,0,0,0,0,0,12,12,12,12,12,12
0,4,13,13,13,13,4,13,13,13,13,4,0
0,14,3,3,3,3,14,0,0,0,0,14,0
0,14,3,3,3,3,14,0,0,0,0,14,0
0,14,3,3,3,3,14,0,0,0,0,14,0
0,14,7,3,3,3,14,0,0,0,0,14,0
0,4,13,13,13,13,4,13,13,13,13,4,0
0,0,0,0,0,0,0,15,15,15,15,15,15
endlayer

layer
0,0,0,0,0,0,0,0,0,0,0,0,0
0,4,5,5,5,5,4,12,12,12,12,12,12
0,5,0,0,0,0,5,13,13,13,13,4,0
0,5,0,0,0,17,5,0,0,0,16,5,0
0,5,0,0,0,17,5,0,0,0,16,5,0
0,5,0,0,0,0,5,13,13,13,13,4,0
0,4,5,5,5,5,4,15,15,15,15,15,15
0,0,0,0,0,0,0,0,0,0,0,0,0
endlayer

layer
0,0,0,0,0,0,0,0,0,0,0,0,0
0,4,5,8,8,5,4,0,0,0,0,0,0
0,5,0,0,0,0,5,12,12,12,12,12,12
0,8,0,0,0,0,5,13,13,13,13,4,0
0,8,0,0,0,0,5,13,13,13,13,4,0
0,5,0,0,0,0,5,15,15,15,15,15,15
0,4,5,8,8,5,4,0,0,0,0,0,0
0,0,0,0,0,0,0,0,0,0,0,0,0
endlayer

layer
0,0,0,0,0,0,0,0,0,0,0,0,0
0,4,5,5,5,5,4,0,0,0,0,0,0
0,5,0,0,0,0,5,0,0,0,0,0,0
0,5,0,0,0,0,5,12,12,12,12,12,12
0,5,0,0,0,0,5,15,15,15,15,15,15
0,5,0,0,0,0,5,0,0,0,0,0,0
0,4,5,5,5,5,4,0,0,0,0,0,0
0,0,0,0,0,0,0,0,0,0,0,0,0
endlayer

layer
12,12,12,12,12,12,12,12,0,0,0,0,0
0,4,13,13,13,13,4,0,0,0,0,0,0
0,14,0,0,0,0,14,0,0,0,0,0,0
0,14,0,0,0,0,14,0,0,0,0,0,0
0,14,0,0,0,0,14,0,0,0,0,0,0
0,14,0,0,0,0,14,0,0,0,0,0,0
0,4,13,13,13,13,4,0,0,0,0,0,0
15,15,15,15,15,15,15,15,0,0,0,0,0
endlayer

layer
0,0,0,0,0,0,0,0,0,0,0,0,0
12,12,12,12,12,12,12,12,0,0,0,0,0
0,4,13,13,13,13,4,0,0,0,0,0,0
0,5,11,0,0,16,5,0,0,0,0,0,0
0,5,11,0,0,16,5,0,0,0,0,0,0
0,4,13,13,13,13,4,0,0,0,0,0,0
15,15,15,15,15,15,15,15,0,0,0,0,0
0,0,0,0,0,0,0,0,0,0,0,0,0
endlayer

layer
0,0,0,0,0,0,0,0,0,0,0,0,0
0,0,0,0,0,0,0,0,0,0,0,0,0
12,12,12,12,12,12,12,12,0,0,0,0,0
0,4,13,13,13,13,4,0,0,0,0,0,0
0,4,13,13,13,13,4,0,0,0,0,0,0
15,15,15,15,15,15,15,15,0,0,0,0,0
0,0,0,0,0,0,0,0,0,0,0,0,0
0,0,0,0,0,0,0,0,0,0,0,0,0
endlayer

layer
0,0,0,0,0,0,0,0,0,0,0,0,0
0,0,0,0,0,0,0,0,0,0,0,0,0
0,0,0,0,0,0,0,0,0,0,0,0,0
12,12,12,12,12,12,12,12,0,0,0,0,0
15,15,15,15,15,15,15,15,0,0,0,0,0
0,0,0,0,0,0,0,0,0,0,0,0,0
0,0,0,0,0,0,0,0,0,0,0,0,0
0,0,0,0,0,0,0,0,0,0,0,0,0
endlayer

