
# Created by Ruins mod version 13.6 Ingame Parser
# authoring Player: ToonCop

weight=1
unique=1
embed_into_distance=0
acceptable_target_blocks=
unacceptable_target_blocks=flowing_water,water,flowing_lava,lava
dimensions=16,19,18
allowable_overhang=0
max_leveling=2
leveling_buffer=0
preserve_water=0
preserve_lava=0

rule1=0,100,minecraft:log2-1
rule2=0,100,minecraft:stone_slab-13
rule3=0,100,minecraft:stonebrick-0
rule4=0,100,minecraft:stone_slab-5
rule5=0,100,minecraft:fence-0
rule6=0,100,minecraft:wooden_slab-13
rule7=0,100,minecraft:crafting_table-0
rule8=0,100,ChestGenHook:dungeonChest:5-5
rule9=0,100,minecraft:log2-9
rule10=0,100,minecraft:log2-5
rule11=0,100,IInventory;minecraft:furnace;minecraft:coal#15#0#1-3
rule12=0,100,IInventory;minecraft:furnace;minecraft:coal#15#0#1-2
rule13=7,100,minecraft:wooden_door-2
rule14=7,100,minecraft:torch-1
rule15=7,100,minecraft:torch-5
rule16=0,100,minecraft:ladder-5
rule17=0,100,minecraft:wooden_door-9
rule18=0,100,minecraft:wooden_door-8
rule19=0,100,minecraft:glass_pane-0
rule20=0,100,minecraft:dark_oak_stairs-4
rule21=0,100,minecraft:dark_oak_stairs-1
rule22=0,100,minecraft:wooden_slab-5
rule23=0,100,minecraft:planks-5
rule24=0,100,ChestGenHook:dungeonChest:5-4
rule25=0,100,minecraft:dark_oak_stairs-2
rule26=0,100,minecraft:dark_oak_stairs-7
rule27=0,100,minecraft:dark_oak_stairs-6
rule28=0,100,minecraft:dark_oak_stairs-3
rule29=7,100,minecraft:torch-2

layer
0,0,0,0,0,0,0,0,0,0,0,0,0,0,0,0,0,0
0,0,0,0,0,0,0,0,0,0,0,0,0,0,0,0,0,0
0,0,1,0,0,0,0,0,0,0,0,0,0,0,0,1,0,0
0,0,0,0,0,0,0,0,0,0,0,0,0,0,0,0,0,0
0,0,0,0,0,0,0,0,0,0,0,0,0,0,0,0,0,0
0,0,0,0,0,0,0,0,0,0,0,0,0,0,0,0,0,0
0,0,0,0,0,0,0,0,0,0,0,0,0,0,0,0,0,0
0,0,0,0,0,0,0,0,0,0,0,0,0,0,0,0,0,0
0,0,0,0,0,0,0,0,0,0,0,0,0,0,0,0,0,0
0,0,0,0,0,0,0,0,0,0,0,0,0,0,0,0,0,0
0,0,0,0,0,0,0,0,0,0,0,0,0,0,0,0,0,0
0,0,1,0,0,0,0,1,0,0,1,0,0,0,0,1,0,0
0,0,0,0,0,0,0,0,0,0,0,0,0,0,0,0,0,0
0,0,0,0,0,0,0,1,0,0,1,0,0,0,0,0,0,0
0,0,0,0,0,0,0,0,2,2,0,0,0,0,0,0,0,0
0,0,0,0,0,0,0,0,3,3,0,0,0,0,0,0,0,0
0,0,0,0,0,0,0,0,4,4,0,0,0,0,0,0,0,0
0,0,0,0,0,0,0,0,0,0,0,0,0,0,0,0,0,0
0,0,0,0,0,0,0,0,0,0,0,0,0,0,0,0,0,0
endlayer

layer
0,0,0,0,0,0,0,0,0,0,0,0,0,0,0,0,0,0
0,0,0,0,0,0,0,0,0,0,0,0,0,0,0,0,0,0
0,0,1,5,5,5,5,5,5,5,5,5,5,5,5,1,0,0
0,0,5,6,6,6,6,6,6,6,6,6,6,6,6,5,0,0
0,0,5,6,6,6,6,6,6,6,6,6,6,6,6,5,0,0
0,0,5,6,6,6,6,6,7,7,6,6,6,6,6,5,0,0
0,0,5,6,6,6,6,6,8,8,6,6,6,6,6,5,0,0
0,0,5,6,6,6,6,6,6,6,6,6,6,6,6,5,0,0
0,0,5,6,6,6,6,6,6,6,6,6,6,6,6,5,0,0
0,0,5,6,6,6,6,6,6,6,6,6,6,6,6,5,0,0
0,0,5,6,6,6,6,6,6,6,6,6,6,6,6,5,0,0
0,0,1,5,5,5,5,1,6,6,1,5,5,5,5,1,0,0
0,0,0,0,0,0,0,6,6,6,6,0,0,0,0,0,0,0
0,0,0,0,0,0,0,1,6,6,1,0,0,0,0,0,0,0
0,0,0,0,0,0,0,0,4,4,0,0,0,0,0,0,0,0
0,0,0,0,0,0,0,0,0,0,0,0,0,0,0,0,0,0
0,0,0,0,0,0,0,0,0,0,0,0,0,0,0,0,0,0
0,0,0,0,0,0,0,0,0,0,0,0,0,0,0,0,0,0
0,0,0,0,0,0,0,0,0,0,0,0,0,0,0,0,0,0
endlayer

layer
0,0,0,0,0,0,0,0,0,0,0,0,0,0,0,0,0,0
0,0,0,0,0,0,0,0,0,0,0,0,0,0,0,0,0,0
0,0,1,9,9,9,9,9,9,9,9,9,9,9,9,1,0,0
0,0,10,5,0,0,0,0,0,0,0,0,0,0,5,10,0,0
0,0,10,0,0,0,0,0,0,0,0,0,0,0,0,10,0,0
0,0,10,0,0,0,0,12,0,0,11,0,0,0,0,10,0,0
0,0,10,0,0,0,0,1,9,9,1,0,0,0,0,10,0,0
0,0,10,0,0,0,0,0,0,0,0,0,0,0,0,10,0,0
0,0,10,0,0,0,0,0,0,0,0,0,0,0,0,10,0,0
0,0,10,0,0,0,0,0,0,0,0,0,0,0,0,10,0,0
0,0,10,5,0,0,0,0,0,0,0,0,0,0,5,10,0,0
0,0,1,9,9,9,9,1,13,13,1,9,9,9,9,1,0,0
0,0,0,0,0,0,0,5,0,0,5,0,0,0,0,0,0,0
0,0,0,0,0,0,0,1,0,0,1,0,0,0,0,0,0,0
0,0,0,0,0,0,0,14,0,0,14,0,0,0,0,0,0,0
0,0,0,0,0,0,0,0,0,0,0,0,0,0,0,0,0,0
0,0,0,0,0,0,0,0,0,0,0,0,0,0,0,0,0,0
0,0,0,0,0,0,0,0,0,0,0,0,0,0,0,0,0,0
0,0,0,0,0,0,0,0,0,0,0,0,0,0,0,0,0,0
endlayer

layer
0,0,0,0,0,0,0,0,0,0,0,0,0,0,0,0,0,0
0,0,0,0,0,0,0,0,0,0,0,0,0,0,0,0,0,0
0,0,1,3,3,3,3,1,3,3,1,3,3,3,3,1,0,0
0,0,3,15,0,0,0,0,16,16,0,0,0,0,15,3,0,0
0,0,3,0,0,0,0,0,0,0,0,0,0,0,0,3,0,0
0,0,3,0,0,0,0,0,0,0,0,0,0,0,0,3,0,0
0,0,3,0,0,0,0,15,0,0,15,0,0,0,0,3,0,0
0,0,3,0,0,0,0,0,0,0,0,0,0,0,0,3,0,0
0,0,3,0,0,0,0,0,0,0,0,0,0,0,0,3,0,0
0,0,3,0,0,0,0,0,0,0,0,0,0,0,0,3,0,0
0,0,3,15,0,0,0,0,0,0,0,0,0,0,15,3,0,0
0,0,1,3,3,3,3,1,18,17,1,3,3,3,3,1,0,0
0,0,0,0,0,0,0,0,0,0,0,0,0,0,0,0,0,0
0,0,0,0,0,0,0,1,0,0,1,0,0,0,0,0,0,0
0,0,0,0,0,0,0,0,0,0,0,0,0,0,0,0,0,0
0,0,0,0,0,0,0,0,0,0,0,0,0,0,0,0,0,0
0,0,0,0,0,0,0,0,0,0,0,0,0,0,0,0,0,0
0,0,0,0,0,0,0,0,0,0,0,0,0,0,0,0,0,0
0,0,0,0,0,0,0,0,0,0,0,0,0,0,0,0,0,0
endlayer

layer
0,0,0,0,0,0,0,0,0,0,0,0,0,0,0,0,0,0
0,0,0,0,0,0,0,0,0,0,0,0,0,0,0,0,0,0
0,0,1,3,19,19,3,1,3,3,1,3,19,19,3,1,0,0
0,0,3,0,0,0,0,0,16,16,0,0,0,0,0,3,0,0
0,0,19,0,0,0,0,0,0,0,0,0,0,0,0,19,0,0
0,0,19,0,0,0,0,0,0,0,0,0,0,0,0,19,0,0
0,0,3,0,0,0,0,0,0,0,0,0,0,0,0,3,0,0
0,0,3,0,0,0,0,0,0,0,0,0,0,0,0,3,0,0
0,0,19,0,0,0,0,0,0,0,0,0,0,0,0,19,0,0
0,0,19,0,0,0,0,0,0,0,0,0,0,0,0,19,0,0
0,0,3,0,0,0,0,0,0,0,0,0,0,0,0,3,0,0
0,0,1,3,19,19,3,1,19,19,1,3,19,19,3,1,0,0
0,0,0,0,0,0,0,0,0,0,0,0,0,0,0,0,0,0
0,0,0,0,0,0,0,20,20,20,20,0,0,0,0,0,0,0
0,0,0,0,0,0,0,21,21,21,21,0,0,0,0,0,0,0
0,0,0,0,0,0,0,0,0,0,0,0,0,0,0,0,0,0
0,0,0,0,0,0,0,0,0,0,0,0,0,0,0,0,0,0
0,0,0,0,0,0,0,0,0,0,0,0,0,0,0,0,0,0
0,0,0,0,0,0,0,0,0,0,0,0,0,0,0,0,0,0
endlayer

layer
0,0,0,0,0,0,0,0,0,0,0,0,0,0,0,0,0,0
0,0,0,0,0,0,0,0,0,0,0,0,0,0,0,0,0,0
0,0,1,3,3,3,3,1,3,3,1,3,3,3,3,1,0,0
0,0,3,0,0,0,0,0,16,16,0,0,0,0,0,3,0,0
0,0,3,0,0,0,0,0,0,0,0,0,0,0,0,3,0,0
0,0,3,0,0,0,0,0,0,0,0,0,0,0,0,3,0,0
0,0,3,0,0,0,0,0,0,0,0,0,0,0,0,3,0,0
0,0,3,0,0,0,0,0,0,0,0,0,0,0,0,3,0,0
0,0,3,0,0,0,0,0,0,0,0,0,0,0,0,3,0,0
0,0,3,0,0,0,0,0,0,0,0,0,0,0,0,3,0,0
0,0,3,0,0,0,0,0,0,0,0,0,0,0,0,3,0,0
0,0,1,3,3,3,3,1,9,9,1,3,3,3,3,1,0,0
0,0,0,0,0,0,0,22,22,22,22,0,0,0,0,0,0,0
0,0,0,0,0,0,0,0,0,0,0,0,0,0,0,0,0,0
0,0,0,0,0,0,0,0,0,0,0,0,0,0,0,0,0,0
0,0,0,0,0,0,0,0,0,0,0,0,0,0,0,0,0,0
0,0,0,0,0,0,0,0,0,0,0,0,0,0,0,0,0,0
0,0,0,0,0,0,0,0,0,0,0,0,0,0,0,0,0,0
0,0,0,0,0,0,0,0,0,0,0,0,0,0,0,0,0,0
endlayer

layer
0,0,0,0,0,0,0,0,0,0,0,0,0,0,0,0,0,0
0,6,0,0,0,0,0,0,0,0,0,0,0,0,0,0,6,0
0,6,1,9,9,9,9,1,3,3,1,9,9,9,9,1,6,0
0,6,10,0,0,0,0,0,16,16,0,0,0,0,0,10,6,0
0,6,10,0,0,0,0,0,0,0,0,0,0,0,0,10,6,0
0,6,10,0,0,0,0,0,0,0,0,0,0,0,0,10,6,0
0,6,10,0,0,0,0,0,0,0,0,0,0,0,0,10,6,0
0,6,10,0,0,0,0,0,0,0,0,0,0,0,0,10,6,0
0,6,10,0,0,0,0,0,0,0,0,0,0,0,0,10,6,0
0,6,10,0,0,0,0,0,0,0,0,0,0,0,0,10,6,0
0,6,10,0,0,0,0,0,0,0,0,0,0,0,0,10,6,0
0,6,1,9,9,9,9,1,3,3,1,9,9,9,9,1,6,0
0,6,0,0,0,0,0,0,0,0,0,0,0,0,0,0,6,0
0,0,0,0,0,0,0,0,0,0,0,0,0,0,0,0,0,0
0,0,0,0,0,0,0,0,0,0,0,0,0,0,0,0,0,0
0,0,0,0,0,0,0,0,0,0,0,0,0,0,0,0,0,0
0,0,0,0,0,0,0,0,0,0,0,0,0,0,0,0,0,0
0,0,0,0,0,0,0,0,0,0,0,0,0,0,0,0,0,0
0,0,0,0,0,0,0,0,0,0,0,0,0,0,0,0,0,0
endlayer

layer
0,0,0,0,0,0,0,0,0,0,0,0,0,0,0,0,0,0
0,0,22,6,0,0,0,0,0,0,0,0,0,0,6,22,0,0
0,0,22,3,3,3,3,1,3,3,1,3,3,3,3,22,0,0
0,0,22,23,0,0,0,0,16,16,0,0,0,0,6,22,0,0
0,0,22,23,0,0,0,0,0,0,0,0,0,0,6,22,0,0
0,0,22,23,0,0,0,0,0,0,0,0,0,0,6,22,0,0
0,0,22,23,0,0,0,0,0,0,0,0,0,0,6,22,0,0
0,0,22,23,0,0,0,0,0,0,0,0,0,0,6,22,0,0
0,0,22,23,0,0,0,0,0,0,0,0,0,0,6,22,0,0
0,0,22,23,0,0,0,0,0,0,0,0,0,0,6,22,0,0
0,0,22,23,0,0,0,0,0,0,0,0,0,0,6,22,0,0
0,0,22,3,3,3,3,1,3,3,1,3,3,3,3,22,0,0
0,0,22,6,0,0,0,0,0,0,0,0,0,0,6,22,0,0
0,0,0,0,0,0,0,0,0,0,0,0,0,0,0,0,0,0
0,0,0,0,0,0,0,0,0,0,0,0,0,0,0,0,0,0
0,0,0,0,0,0,0,0,0,0,0,0,0,0,0,0,0,0
0,0,0,0,0,0,0,0,0,0,0,0,0,0,0,0,0,0
0,0,0,0,0,0,0,0,0,0,0,0,0,0,0,0,0,0
0,0,0,0,0,0,0,0,0,0,0,0,0,0,0,0,0,0
endlayer

layer
0,0,0,0,0,0,0,0,0,0,0,0,0,0,0,0,0,0
0,0,0,0,22,6,0,0,0,0,0,0,6,22,0,0,0,0
0,0,0,0,22,3,3,1,3,3,1,3,3,22,0,0,0,0
0,0,0,0,22,23,0,0,16,16,0,0,23,22,0,0,0,0
0,0,0,0,22,23,0,0,0,0,0,0,23,22,0,0,0,0
0,0,0,0,22,23,0,0,0,0,0,0,23,22,0,0,0,0
0,0,0,0,22,23,0,0,0,0,0,0,23,22,0,0,0,0
0,0,0,0,22,23,0,0,0,0,0,0,23,22,0,0,0,0
0,0,0,0,22,23,0,0,0,0,0,0,23,22,0,0,0,0
0,0,0,0,22,23,0,0,0,0,0,0,23,22,0,0,0,0
0,0,0,0,22,23,0,0,0,0,0,0,23,22,0,0,0,0
0,0,0,0,22,3,3,1,3,3,1,3,3,22,0,0,0,0
0,0,0,0,22,6,0,0,0,0,0,0,6,22,0,0,0,0
0,0,0,0,0,0,0,0,0,0,0,0,0,0,0,0,0,0
0,0,0,0,0,0,0,0,0,0,0,0,0,0,0,0,0,0
0,0,0,0,0,0,0,0,0,0,0,0,0,0,0,0,0,0
0,0,0,0,0,0,0,0,0,0,0,0,0,0,0,0,0,0
0,0,0,0,0,0,0,0,0,0,0,0,0,0,0,0,0,0
0,0,0,0,0,0,0,0,0,0,0,0,0,0,0,0,0,0
endlayer

layer
0,0,0,0,0,0,0,0,0,0,0,0,0,0,0,0,0,0
0,0,0,0,0,0,22,22,22,22,22,22,0,0,0,0,0,0
0,0,0,0,0,0,22,1,3,3,1,22,0,0,0,0,0,0
0,0,0,0,0,0,22,10,16,16,10,22,0,0,0,0,0,0
0,0,0,0,0,0,22,10,23,23,10,22,0,0,0,0,0,0
0,0,0,0,0,0,22,10,23,23,10,22,0,0,0,0,0,0
0,0,0,0,0,0,22,10,23,23,10,22,0,0,0,0,0,0
0,0,0,0,0,0,22,10,23,23,10,22,0,0,0,0,0,0
0,0,0,0,0,0,22,10,23,23,10,22,0,0,0,0,0,0
0,0,0,0,0,0,22,10,23,23,10,22,0,0,0,0,0,0
0,0,0,0,0,0,22,10,23,23,10,22,0,0,0,0,0,0
0,0,0,0,0,0,22,1,3,3,1,22,0,0,0,0,0,0
0,0,0,0,0,0,22,22,22,22,22,22,0,0,0,0,0,0
0,0,0,0,0,0,0,0,0,0,0,0,0,0,0,0,0,0
0,0,0,0,0,0,0,0,0,0,0,0,0,0,0,0,0,0
0,0,0,0,0,0,0,0,0,0,0,0,0,0,0,0,0,0
0,0,0,0,0,0,0,0,0,0,0,0,0,0,0,0,0,0
0,0,0,0,0,0,0,0,0,0,0,0,0,0,0,0,0,0
0,0,0,0,0,0,0,0,0,0,0,0,0,0,0,0,0,0
endlayer

layer
0,0,0,0,0,0,0,0,0,0,0,0,0,0,0,0,0,0
0,0,0,0,0,0,0,0,0,0,0,0,0,0,0,0,0,0
0,0,0,0,0,0,0,1,3,3,1,0,0,0,0,0,0,0
0,0,0,0,0,0,0,3,0,0,3,0,0,0,0,0,0,0
0,0,0,0,0,0,0,3,0,0,3,0,0,0,0,0,0,0
0,0,0,0,0,0,0,3,0,0,3,0,0,0,0,0,0,0
0,0,0,0,0,0,0,3,0,0,3,0,0,0,0,0,0,0
0,0,0,0,0,0,0,3,0,0,3,0,0,0,0,0,0,0
0,0,0,0,0,0,0,3,0,0,3,0,0,0,0,0,0,0
0,0,0,0,0,0,0,3,0,0,3,0,0,0,0,0,0,0
0,0,0,0,0,0,0,3,24,24,3,0,0,0,0,0,0,0
0,0,0,0,0,0,0,1,3,3,1,0,0,0,0,0,0,0
0,0,0,0,0,0,0,0,0,0,0,0,0,0,0,0,0,0
0,0,0,0,0,0,0,0,0,0,0,0,0,0,0,0,0,0
0,0,0,0,0,0,0,0,0,0,0,0,0,0,0,0,0,0
0,0,0,0,0,0,0,0,0,0,0,0,0,0,0,0,0,0
0,0,0,0,0,0,0,0,0,0,0,0,0,0,0,0,0,0
0,0,0,0,0,0,0,0,0,0,0,0,0,0,0,0,0,0
0,0,0,0,0,0,0,0,0,0,0,0,0,0,0,0,0,0
endlayer

layer
0,0,0,0,0,0,0,0,0,0,0,0,0,0,0,0,0,0
0,0,0,0,0,0,0,0,0,0,0,0,0,0,0,0,0,0
0,0,0,0,0,0,0,1,19,19,1,0,0,0,0,0,0,0
0,0,0,0,0,0,0,3,0,0,3,0,0,0,0,0,0,0
0,0,0,0,0,0,0,3,0,0,3,0,0,0,0,0,0,0
0,0,0,0,0,0,0,3,0,0,3,0,0,0,0,0,0,0
0,0,0,0,0,0,0,3,0,0,3,0,0,0,0,0,0,0
0,0,0,0,0,0,0,3,0,0,3,0,0,0,0,0,0,0
0,0,0,0,0,0,0,3,0,0,3,0,0,0,0,0,0,0
0,0,0,0,0,0,0,3,0,0,3,0,0,0,0,0,0,0
0,0,0,0,0,0,0,3,0,0,3,0,0,0,0,0,0,0
0,0,0,0,0,0,0,1,19,19,1,0,0,0,0,0,0,0
0,0,0,0,0,0,0,0,0,0,0,0,0,0,0,0,0,0
0,0,0,0,0,0,0,0,0,0,0,0,0,0,0,0,0,0
0,0,0,0,0,0,0,0,0,0,0,0,0,0,0,0,0,0
0,0,0,0,0,0,0,0,0,0,0,0,0,0,0,0,0,0
0,0,0,0,0,0,0,0,0,0,0,0,0,0,0,0,0,0
0,0,0,0,0,0,0,0,0,0,0,0,0,0,0,0,0,0
0,0,0,0,0,0,0,0,0,0,0,0,0,0,0,0,0,0
endlayer

layer
0,0,0,0,0,0,0,0,0,0,0,0,0,0,0,0,0,0
0,0,0,0,0,0,0,0,0,0,0,0,0,0,0,0,0,0
0,0,0,0,0,0,0,1,19,19,1,0,0,0,0,0,0,0
0,0,0,0,0,0,0,3,0,0,3,0,0,0,0,0,0,0
0,0,0,0,0,0,0,3,0,0,3,0,0,0,0,0,0,0
0,0,0,0,0,0,0,3,0,0,3,0,0,0,0,0,0,0
0,0,0,0,0,0,0,3,0,0,3,0,0,0,0,0,0,0
0,0,0,0,0,0,0,3,0,0,3,0,0,0,0,0,0,0
0,0,0,0,0,0,0,3,0,0,3,0,0,0,0,0,0,0
0,0,0,0,0,0,0,3,0,0,3,0,0,0,0,0,0,0
0,0,0,0,0,0,0,3,0,0,3,0,0,0,0,0,0,0
0,0,0,0,0,0,0,1,19,19,1,0,0,0,0,0,0,0
0,0,0,0,0,0,0,0,0,0,0,0,0,0,0,0,0,0
0,0,0,0,0,0,0,0,0,0,0,0,0,0,0,0,0,0
0,0,0,0,0,0,0,0,0,0,0,0,0,0,0,0,0,0
0,0,0,0,0,0,0,0,0,0,0,0,0,0,0,0,0,0
0,0,0,0,0,0,0,0,0,0,0,0,0,0,0,0,0,0
0,0,0,0,0,0,0,0,0,0,0,0,0,0,0,0,0,0
0,0,0,0,0,0,0,0,0,0,0,0,0,0,0,0,0,0
endlayer

layer
0,0,0,0,0,0,0,0,0,0,0,0,0,0,0,0,0,0
0,0,0,0,0,0,28,27,0,0,26,25,0,0,0,0,0,0
0,0,0,0,0,0,28,1,3,3,1,25,0,0,0,0,0,0
0,0,0,0,0,0,28,3,0,0,3,25,0,0,0,0,0,0
0,0,0,0,0,0,28,3,0,0,3,25,0,0,0,0,0,0
0,0,0,0,0,0,28,3,0,0,3,25,0,0,0,0,0,0
0,0,0,0,0,0,28,3,0,0,3,25,0,0,0,0,0,0
0,0,0,0,0,0,28,3,0,0,3,25,0,0,0,0,0,0
0,0,0,0,0,0,28,3,0,0,3,25,0,0,0,0,0,0
0,0,0,0,0,0,28,3,0,0,3,25,0,0,0,0,0,0
0,0,0,0,0,0,28,3,0,0,3,25,0,0,0,0,0,0
0,0,0,0,0,0,28,1,3,3,1,25,0,0,0,0,0,0
0,0,0,0,0,0,28,27,0,0,26,25,0,0,0,0,0,0
0,0,0,0,0,0,0,0,0,0,0,0,0,0,0,0,0,0
0,0,0,0,0,0,0,0,0,0,0,0,0,0,0,0,0,0
0,0,0,0,0,0,0,0,0,0,0,0,0,0,0,0,0,0
0,0,0,0,0,0,0,0,0,0,0,0,0,0,0,0,0,0
0,0,0,0,0,0,0,0,0,0,0,0,0,0,0,0,0,0
0,0,0,0,0,0,0,0,0,0,0,0,0,0,0,0,0,0
endlayer

layer
0,0,0,0,0,0,0,0,0,0,0,0,0,0,0,0,0,0
0,0,0,0,0,0,0,28,27,26,25,0,0,0,0,0,0,0
0,0,0,0,0,0,0,28,3,3,25,0,0,0,0,0,0,0
0,0,0,0,0,0,0,28,14,14,25,0,0,0,0,0,0,0
0,0,0,0,0,0,0,28,0,0,25,0,0,0,0,0,0,0
0,0,0,0,0,0,0,28,0,0,25,0,0,0,0,0,0,0
0,0,0,0,0,0,0,28,0,0,25,0,0,0,0,0,0,0
0,0,0,0,0,0,0,28,0,0,25,0,0,0,0,0,0,0
0,0,0,0,0,0,0,28,0,0,25,0,0,0,0,0,0,0
0,0,0,0,0,0,0,28,29,29,25,0,0,0,0,0,0,0
0,0,0,0,0,0,0,28,7,7,25,0,0,0,0,0,0,0
0,0,0,0,0,0,0,28,3,3,25,0,0,0,0,0,0,0
0,0,0,0,0,0,0,28,27,26,25,0,0,0,0,0,0,0
0,0,0,0,0,0,0,0,0,0,0,0,0,0,0,0,0,0
0,0,0,0,0,0,0,0,0,0,0,0,0,0,0,0,0,0
0,0,0,0,0,0,0,0,0,0,0,0,0,0,0,0,0,0
0,0,0,0,0,0,0,0,0,0,0,0,0,0,0,0,0,0
0,0,0,0,0,0,0,0,0,0,0,0,0,0,0,0,0,0
0,0,0,0,0,0,0,0,0,0,0,0,0,0,0,0,0,0
endlayer

layer
0,0,0,0,0,0,0,0,0,0,0,0,0,0,0,0,0,0
0,0,0,0,0,0,0,0,28,25,0,0,0,0,0,0,0,0
0,0,0,0,0,0,0,0,28,25,0,0,0,0,0,0,0,0
0,0,0,0,0,0,0,0,28,25,0,0,0,0,0,0,0,0
0,0,0,0,0,0,0,0,28,25,0,0,0,0,0,0,0,0
0,0,0,0,0,0,0,0,28,25,0,0,0,0,0,0,0,0
0,0,0,0,0,0,0,0,28,25,0,0,0,0,0,0,0,0
0,0,0,0,0,0,0,0,28,25,0,0,0,0,0,0,0,0
0,0,0,0,0,0,0,0,28,25,0,0,0,0,0,0,0,0
0,0,0,0,0,0,0,0,28,25,0,0,0,0,0,0,0,0
0,0,0,0,0,0,0,0,28,25,0,0,0,0,0,0,0,0
0,0,0,0,0,0,0,0,28,25,0,0,0,0,0,0,0,0
0,0,0,0,0,0,0,0,28,25,0,0,0,0,0,0,0,0
0,0,0,0,0,0,0,0,0,0,0,0,0,0,0,0,0,0
0,0,0,0,0,0,0,0,0,0,0,0,0,0,0,0,0,0
0,0,0,0,0,0,0,0,0,0,0,0,0,0,0,0,0,0
0,0,0,0,0,0,0,0,0,0,0,0,0,0,0,0,0,0
0,0,0,0,0,0,0,0,0,0,0,0,0,0,0,0,0,0
0,0,0,0,0,0,0,0,0,0,0,0,0,0,0,0,0,0
endlayer

