
# Created by Ruins mod version 14.4 Ingame Parser
# authoring Player: Drock1994

weight=1
embed_into_distance=0
acceptable_target_blocks=
unacceptable_target_blocks=flowing_water,water,flowing_lava,lava
dimensions=8,13,15
allowable_overhang=0
max_leveling=2
leveling_buffer=0
preserve_water=0
preserve_lava=0

rule1=0,100,minecraft:sandstone-0
rule2=0,100,minecraft:wooden_door-0
rule3=0,100,ChestGenHook:dungeonChest:5-5
rule4=0,100,minecraft:crafting_table-0
rule5=0,100,minecraft:wooden_door-8
rule6=0,100,minecraft:glass-0
rule7=2,100,minecraft:torch-3
rule8=2,100,minecraft:torch-4
rule9=2,100,minecraft:torch-1
rule10=0,100,minecraft:glowstone-0

layer
1,1,1,1,1,1,1,1,1,1,1,1,1,1,1
1,1,1,1,1,1,1,1,1,1,1,1,1,1,1
1,1,1,1,1,1,1,1,1,1,1,1,1,1,1
1,1,1,1,1,1,1,1,1,1,1,1,1,1,1
1,1,1,1,1,1,1,1,1,1,1,1,1,1,1
1,1,1,1,1,1,1,1,1,1,1,1,1,1,1
1,1,1,1,1,1,1,1,1,1,1,1,1,1,1
1,1,1,1,1,1,1,1,1,1,1,1,1,1,1
1,1,1,1,1,1,1,1,1,1,1,1,1,1,1
1,1,1,1,1,1,1,1,1,1,1,1,1,1,1
1,1,1,1,1,1,1,1,1,1,1,1,1,1,1
1,1,1,1,1,1,1,1,1,1,1,1,1,1,1
1,1,1,1,1,1,1,1,1,1,1,1,1,1,1
endlayer

layer
0,0,0,0,0,0,0,0,0,0,0,0,0,0,0
0,1,1,1,1,0,1,2,1,0,1,1,1,1,0
0,1,0,0,1,1,1,0,1,1,1,0,0,1,0
0,1,0,0,0,0,0,0,0,0,0,0,0,1,0
0,1,0,0,0,0,0,0,0,0,0,0,0,1,0
0,0,1,0,0,0,0,0,0,0,0,0,1,0,0
0,0,1,0,0,0,0,0,0,0,0,0,1,0,0
0,0,1,0,0,0,0,0,0,0,0,0,1,0,0
0,1,0,0,0,0,0,0,0,0,0,0,0,1,0
0,1,0,0,0,0,0,0,0,0,0,0,0,1,0
0,1,3,0,0,1,1,4,1,1,0,0,3,1,0
0,1,1,1,1,0,0,1,0,0,1,1,1,1,0
0,0,0,0,0,0,0,0,0,0,0,0,0,0,0
endlayer

layer
0,0,0,0,0,0,0,0,0,0,0,0,0,0,0
0,1,1,1,0,0,1,5,1,0,0,1,1,1,0
0,1,0,0,1,1,0,0,0,1,1,0,0,1,0
0,1,0,0,0,0,0,0,0,0,0,0,0,1,0
0,0,1,0,0,0,0,0,0,0,0,0,1,0,0
0,0,1,0,0,0,0,0,0,0,0,0,1,0,0
0,1,0,0,0,0,0,0,0,0,0,0,0,1,0
0,0,1,0,0,0,0,0,0,0,0,0,1,0,0
0,0,1,0,0,0,0,0,0,0,0,0,1,0,0
0,1,0,0,0,0,0,0,0,0,0,0,0,1,0
0,1,0,0,1,1,0,0,0,1,1,0,0,1,0
0,1,1,1,0,0,1,1,1,0,0,1,1,1,0
0,0,0,0,0,0,0,0,0,0,0,0,0,0,0
endlayer

layer
0,0,0,0,0,0,0,0,0,0,0,0,0,0,0
0,1,1,0,0,1,1,6,1,1,0,0,1,1,0
0,1,0,1,1,0,0,0,0,0,1,1,0,1,0
0,0,1,8,0,0,0,0,0,0,0,7,1,0,0
0,0,1,0,0,0,0,0,0,0,0,0,1,0,0
0,1,0,0,0,0,0,0,0,0,0,0,0,1,0
0,1,0,0,0,0,0,0,0,0,0,0,0,1,0
0,1,0,0,0,0,0,0,0,0,0,0,0,1,0
0,0,1,0,0,0,0,0,0,0,0,0,1,0,0
0,0,1,8,0,0,0,0,0,0,0,7,1,0,0
0,1,0,1,1,0,0,0,0,0,1,1,0,1,0
0,1,1,0,0,1,1,6,1,1,0,0,1,1,0
0,0,0,0,0,0,0,0,0,0,0,0,0,0,0
endlayer

layer
0,0,0,0,0,0,0,0,0,0,0,0,0,0,0
0,1,0,0,1,1,6,6,6,1,1,0,0,1,0
0,0,1,1,0,0,0,0,0,0,0,1,1,0,0
0,0,1,0,0,0,0,0,0,0,0,0,1,0,0
0,1,0,0,0,0,0,0,0,0,0,0,0,1,0
0,1,0,0,0,0,0,0,0,0,0,0,0,1,0
0,6,0,0,0,0,0,0,0,0,0,0,0,6,0
0,1,0,0,0,0,0,0,0,0,0,0,0,1,0
0,1,0,0,0,0,0,0,0,0,0,0,0,1,0
0,0,1,0,0,0,0,0,0,0,0,0,1,0,0
0,0,1,1,0,0,0,0,0,0,0,1,1,0,0
0,1,0,0,1,1,6,6,6,1,1,0,0,1,0
0,0,0,0,0,0,0,0,0,0,0,0,0,0,0
endlayer

layer
0,0,0,0,0,0,0,0,0,0,0,0,0,0,0
0,1,1,0,0,1,1,6,1,1,0,0,1,1,0
0,1,0,1,1,0,0,0,0,0,1,1,0,1,0
0,0,1,0,0,0,0,0,0,0,0,0,1,0,0
0,0,1,0,0,0,0,0,0,0,0,0,1,0,0
0,1,0,0,0,0,0,0,0,0,0,0,0,1,0
0,1,0,0,0,0,0,0,0,0,0,0,0,1,0
0,1,0,0,0,0,0,0,0,0,0,0,0,1,0
0,0,1,0,0,0,0,0,0,0,0,0,1,0,0
0,0,1,0,0,0,0,0,0,0,0,0,1,0,0
0,1,0,1,1,0,0,0,0,0,1,1,0,1,0
0,1,1,0,0,1,1,6,1,1,0,0,1,1,0
0,0,0,0,0,0,0,0,0,0,0,0,0,0,0
endlayer

layer
0,0,0,0,0,0,0,0,0,0,0,0,0,0,0
0,1,1,1,0,0,1,1,1,0,0,1,1,1,0
0,1,0,0,1,1,0,9,0,1,1,0,0,1,0
0,1,0,0,0,0,0,0,0,0,0,0,0,1,0
0,0,1,0,0,0,0,0,0,0,0,0,1,0,0
0,0,1,0,0,0,0,0,0,0,0,0,1,0,0
0,1,0,0,0,0,0,0,0,0,0,0,0,1,0
0,0,1,0,0,0,0,0,0,0,0,0,1,0,0
0,0,1,0,0,0,0,0,0,0,0,0,1,0,0
0,1,0,0,0,0,0,0,0,0,0,0,0,1,0
0,1,0,0,1,1,0,0,0,1,1,0,0,1,0
0,1,1,1,0,0,1,1,1,0,0,1,1,1,0
0,0,0,0,0,0,0,0,0,0,0,0,0,0,0
endlayer

layer
0,0,0,0,0,0,0,0,0,0,0,0,0,0,0
0,1,1,1,1,0,0,1,0,0,1,1,1,1,0
0,1,1,1,1,1,1,1,1,1,1,1,1,1,0
0,1,1,1,6,1,1,1,1,1,6,1,1,1,0
0,1,1,6,6,6,1,1,1,6,6,6,1,1,0
0,0,1,1,6,6,6,1,6,6,6,1,1,0,0
0,0,1,1,1,6,6,10,6,6,1,1,1,0,0
0,0,1,1,6,6,6,1,6,6,6,1,1,0,0
0,1,1,6,6,6,1,1,1,6,6,6,1,1,0
0,1,1,1,6,1,1,1,1,1,6,1,1,1,0
0,1,1,1,1,1,1,1,1,1,1,1,1,1,0
0,1,1,1,1,0,0,1,0,0,1,1,1,1,0
0,0,0,0,0,0,0,0,0,0,0,0,0,0,0
endlayer

