
# Created by Ruins mod version 13.5 Ingame Parser
# authoring Player: ToonCop

weight=1
embed_into_distance=1
acceptable_target_blocks=
unacceptable_target_blocks=flowing_water,water,flowing_lava,lava
dimensions=12,11,9
allowable_overhang=0
max_leveling=2
leveling_buffer=1
preserve_water=0
preserve_lava=0
preserve_plants=0

rule1=0,100,minecraft:log-0
rule2=0,100,minecraft:cobblestone-0
rule3=1,100,minecraft:wooden_door-0
rule4=0,25,ChestGenHook:dungeonChest:5-3
rule5=0,100,minecraft:fence-0
rule6=0,100,minecraft:planks-0
rule7=0,100,minecraft:oak_stairs-2
rule8=1,100,minecraft:wooden_door-2
rule9=1,100,minecraft:wooden_door-8
rule10=1,100,minecraft:wooden_door-9
rule11=0,100,minecraft:glass_pane-0
rule12=2,100,minecraft:torch-1
rule13=2,100,minecraft:torch-3
rule14=2,100,minecraft:torch-4
rule15=0,100,minecraft:oak_stairs-1
rule16=0,25,ChestGenHook:dungeonChest:5-5
rule17=0,100,ChestGenHook:dungeonChest:5-4
rule18=0,100,minecraft:oak_stairs-3
rule19=0,100,minecraft:oak_stairs-7
rule20=0,100,minecraft:oak_stairs-6
rule21=2,100,minecraft:torch-2
rule22=0,100,minecraft:stone_slab-2
rule23=0,100,minecraft:oak_stairs-0
rule24=0,100,minecraft:iron_bars-0

layer
1,2,2,2,2,2,2,2,1
2,2,2,2,2,2,2,2,2
2,2,2,2,2,2,2,2,2
2,2,2,2,2,2,2,2,2
2,2,2,2,2,2,2,2,2
2,2,2,2,2,2,2,2,2
2,2,2,2,2,2,2,2,2
2,2,2,2,2,2,2,2,2
2,2,2,2,2,2,2,2,2
2,2,2,2,2,2,2,2,2
1,2,2,2,2,2,2,2,1
endlayer

layer
1,2,2,2,2,3,3,2,1
2,0,0,0,0,0,0,0,2
2,5,5,5,0,0,0,4,2
2,0,0,0,0,0,0,4,2
2,5,5,5,0,0,0,0,2
2,0,0,0,0,0,0,0,2
2,5,5,5,0,0,0,0,2
2,0,0,0,0,0,0,4,2
2,6,6,5,0,0,0,4,2
2,6,6,7,0,0,0,0,2
1,2,2,2,2,8,8,2,1
endlayer

layer
1,6,11,11,6,10,9,6,1
6,0,0,0,12,0,0,0,6
6,0,0,0,0,0,0,0,11
11,0,0,0,0,0,0,0,11
11,0,0,0,0,0,0,0,6
11,0,0,0,0,0,0,13,6
6,0,0,0,0,0,0,0,6
6,0,0,0,0,0,0,0,11
6,6,6,14,0,0,0,0,11
6,6,7,0,0,0,0,0,6
1,6,6,6,6,9,10,6,1
endlayer

layer
1,6,6,6,6,6,6,6,1
6,0,0,0,0,0,0,0,6
6,0,0,0,0,0,0,0,6
6,0,0,0,0,0,0,0,6
6,0,0,0,0,0,0,0,6
6,0,0,0,0,0,0,0,6
6,0,0,0,0,0,0,0,6
6,0,0,0,0,0,0,0,6
6,15,6,0,0,0,0,0,6
6,0,0,0,0,0,0,0,6
1,6,6,6,6,6,6,6,1
endlayer

layer
1,1,1,1,1,1,1,1,1
1,6,6,6,6,6,6,6,1
1,6,6,6,6,6,6,6,1
1,6,6,6,6,6,6,6,1
1,6,6,6,6,6,6,6,1
1,6,6,6,6,6,6,6,1
1,6,6,6,6,6,6,6,1
1,15,6,6,6,6,6,6,1
1,0,6,6,6,6,6,6,1
1,0,0,0,6,6,6,6,1
1,1,1,1,1,1,1,1,1
endlayer

layer
6,6,6,1,0,1,6,6,6
6,16,16,0,0,0,16,16,6
6,0,0,0,0,0,0,0,6
6,0,0,0,0,0,0,0,6
6,0,0,0,0,0,0,0,6
6,0,0,0,0,0,0,0,6
6,0,0,0,0,0,0,0,6
6,0,0,0,0,0,0,0,6
6,0,0,0,0,0,0,0,6
6,0,0,0,17,0,17,17,6
6,6,6,1,6,1,6,6,6
endlayer

layer
18,6,6,1,0,1,6,6,7
18,0,0,0,0,0,0,0,7
18,0,0,0,0,0,0,0,7
18,0,0,0,0,0,0,0,7
18,0,0,0,0,0,0,0,7
18,0,0,0,0,0,0,0,7
18,0,0,0,0,0,0,0,7
18,0,0,0,0,0,0,0,7
18,0,0,0,0,0,0,0,7
18,0,0,0,0,0,0,0,7
18,6,6,1,6,1,6,6,7
endlayer

layer
0,6,6,6,1,6,6,6,0
0,6,0,0,0,0,0,6,0
0,6,0,0,0,0,0,6,0
0,6,0,0,0,0,0,6,0
0,6,0,0,0,0,0,6,0
0,6,0,0,0,0,0,6,0
0,6,0,0,0,0,0,6,0
0,6,0,0,0,0,0,6,0
0,6,0,0,0,0,0,6,0
0,6,0,0,0,0,0,6,0
0,6,6,6,0,6,6,6,0
endlayer

layer
0,18,6,6,1,6,6,7,0
0,18,20,0,12,0,19,7,0
0,18,20,0,0,0,19,7,0
0,18,20,0,0,0,19,7,0
0,18,20,0,0,0,19,7,0
0,18,20,0,0,0,19,7,0
0,18,20,0,0,0,19,7,0
0,18,20,0,0,0,19,7,0
0,18,20,0,0,0,19,7,0
0,18,20,0,21,0,19,7,0
0,18,6,6,1,6,6,7,0
endlayer

layer
0,0,18,6,6,6,7,0,0
0,0,18,6,0,6,7,0,0
0,0,18,6,0,6,7,0,0
0,0,18,6,0,6,7,0,0
0,0,18,6,0,6,7,0,0
0,0,18,6,0,6,7,0,0
0,0,18,6,0,6,7,0,0
0,0,18,6,0,6,7,0,0
0,0,18,6,0,6,7,0,0
0,0,18,6,0,6,7,0,0
0,0,18,6,6,6,7,0,0
endlayer

layer
0,0,0,0,22,0,0,0,0
0,0,0,0,22,0,0,0,0
0,0,0,0,22,0,0,0,0
0,0,0,0,22,0,0,0,0
0,0,0,0,23,0,0,0,0
0,0,0,0,6,0,0,0,0
0,0,0,0,15,0,0,0,0
0,0,0,0,22,0,0,0,0
0,0,0,0,22,0,0,0,0
0,0,0,0,22,0,0,0,0
0,0,0,0,22,0,0,0,0
endlayer

layer
0,0,0,0,0,0,0,0,0
0,0,0,0,0,0,0,0,0
0,0,0,0,0,0,0,0,0
0,0,0,0,0,0,0,0,0
0,0,0,0,0,0,0,0,0
0,0,0,0,24,0,0,0,0
0,0,0,0,0,0,0,0,0
0,0,0,0,0,0,0,0,0
0,0,0,0,0,0,0,0,0
0,0,0,0,0,0,0,0,0
0,0,0,0,0,0,0,0,0
endlayer

