
# Created by Ruins mod version 14.4 Ingame Parser
# authoring Player: Drock1994

weight=1
embed_into_distance=7
acceptable_target_blocks=
unacceptable_target_blocks=flowing_water,water,flowing_lava,lava,sand,sandstone
dimensions=13,10,10
allowable_overhang=0
max_leveling=2
leveling_buffer=0
preserve_water=0
preserve_lava=0

rule1=0,100,minecraft:dirt-0
rule2=0,100,minecraft:end_stone-0
rule3=0,100,minecraft:stonebrick-0
rule4=0,100,minecraft:stonebrick-1
rule5=0,100,ChestGenHook:dungeonChest:5-3
rule6=0,100,minecraft:ladder-2
rule7=0,100,ChestGenHook:dungeonChest:5-4
rule8=0,100,minecraft:glowstone-0
rule9=0,100,minecraft:grass-0
rule10=0,100,minecraft:brick_block-0
rule11=0,100,minecraft:carpet-10
rule12=0,100,minecraft:wooden_door-1
rule13=0,100,minecraft:glass_pane-0
rule14=0,100,minecraft:wooden_door-8
rule15=0,100,minecraft:wooden_slab-9
rule16=0,100,minecraft:spruce_stairs-0
rule17=2,100,minecraft:torch-3
rule18=2,100,minecraft:torch-4
rule19=0,100,minecraft:spruce_stairs-1
rule20=0,100,minecraft:wooden_slab-1

layer
1,1,1,1,1,1,1,1,1,1
1,1,1,1,1,1,1,1,1,1
1,1,1,1,1,1,1,1,1,1
1,1,1,2,2,2,2,2,1,1
1,1,1,2,2,2,2,2,1,1
1,1,1,2,2,2,2,2,1,1
1,1,1,2,2,2,2,2,1,1
1,1,1,2,2,2,2,2,1,1
1,1,1,1,1,1,1,1,1,1
1,1,1,1,1,1,1,1,1,1
endlayer

layer
1,1,1,1,1,1,1,1,1,1
1,1,1,1,1,1,1,1,1,1
1,1,3,3,4,4,3,3,3,1
1,1,3,6,0,0,0,5,4,1
1,1,4,0,0,0,0,5,3,1
1,1,3,0,0,0,0,0,4,1
1,1,4,0,0,0,0,0,3,1
1,1,3,0,0,7,7,0,3,1
1,1,3,3,4,3,3,3,3,1
1,1,1,1,1,1,1,1,1,1
endlayer

layer
1,1,1,1,1,1,1,1,1,1
1,1,1,1,1,1,1,1,1,1
1,1,3,3,3,3,4,3,3,1
1,1,3,6,0,0,0,0,3,1
1,1,3,0,0,0,0,0,3,1
1,1,4,0,0,0,0,0,3,1
1,1,3,0,0,0,0,0,4,1
1,1,4,0,0,0,0,0,3,1
1,1,3,3,3,4,3,4,3,1
1,1,1,1,1,1,1,1,1,1
endlayer

layer
1,1,1,1,1,1,1,1,1,1
1,1,1,1,1,1,1,1,1,1
1,1,3,3,4,3,3,3,3,1
1,1,3,6,0,0,0,0,3,1
1,1,4,0,0,0,0,0,4,1
1,1,4,0,0,0,0,0,3,1
1,1,3,0,0,0,0,0,3,1
1,1,3,0,0,0,0,0,3,1
1,1,3,3,3,4,3,3,3,1
1,1,1,1,1,1,1,1,1,1
endlayer

layer
1,1,1,1,1,1,1,1,1,1
1,1,1,1,1,1,1,1,1,1
1,1,3,4,3,8,4,3,3,1
1,1,3,6,0,0,0,0,3,1
1,1,3,0,0,0,0,0,4,1
1,1,8,0,0,0,0,0,8,1
1,1,3,0,0,0,0,0,4,1
1,1,4,0,0,0,0,0,3,1
1,1,3,3,4,8,4,3,3,1
1,1,1,1,1,1,1,1,1,1
endlayer

layer
1,1,1,1,1,1,1,1,1,1
1,1,1,1,1,1,1,1,1,1
1,1,3,3,3,4,3,3,3,1
1,1,3,6,3,3,3,3,4,1
1,1,4,3,3,3,3,3,3,1
1,1,3,3,3,3,3,3,4,1
1,1,4,3,3,3,3,3,3,1
1,1,3,3,3,3,3,3,3,1
1,1,3,3,3,3,3,3,3,1
1,1,1,1,1,1,1,1,1,1
endlayer

layer
9,9,9,9,9,9,9,9,9,9
9,1,1,1,1,1,9,9,9,9
9,1,1,1,1,3,9,9,9,9
9,1,1,6,1,9,9,9,9,9
9,1,1,1,1,3,9,9,9,9
9,1,1,1,1,1,9,9,9,9
9,9,9,9,9,9,9,9,9,9
9,9,9,9,9,9,9,9,9,9
9,9,9,9,9,9,9,9,9,9
9,9,9,9,9,9,9,9,9,9
endlayer

layer
0,0,0,0,0,0,0,0,0,0
0,10,10,10,10,10,0,0,0,0
0,10,11,11,11,10,0,0,0,0
0,10,11,11,11,12,0,0,0,0
0,10,11,11,11,10,0,0,0,0
0,10,10,10,10,10,0,0,0,0
0,0,0,0,0,0,0,0,0,0
0,0,0,0,0,0,0,0,0,0
0,0,0,0,0,0,0,0,0,0
0,0,0,0,0,0,0,0,0,0
endlayer

layer
0,0,0,0,0,0,0,0,0,0
0,10,10,13,10,10,0,0,0,0
0,10,0,0,0,10,0,0,0,0
0,13,0,0,0,14,0,0,0,0
0,10,0,0,0,10,0,0,0,0
0,10,10,13,10,10,0,0,0,0
0,0,0,0,0,0,0,0,0,0
0,0,0,0,0,0,0,0,0,0
0,0,0,0,0,0,0,0,0,0
0,0,0,0,0,0,0,0,0,0
endlayer

layer
15,15,15,15,15,15,15,0,0,0
0,10,10,10,10,10,0,0,0,0
0,10,0,0,0,10,0,0,0,0
0,10,0,0,0,10,0,0,0,0
0,10,0,0,0,10,0,0,0,0
0,10,10,10,10,10,0,0,0,0
15,15,15,15,15,15,15,0,0,0
0,0,0,0,0,0,0,0,0,0
0,0,0,0,0,0,0,0,0,0
0,0,0,0,0,0,0,0,0,0
endlayer

layer
0,0,0,0,0,0,0,0,0,0
16,16,16,16,16,16,16,0,0,0
0,10,0,0,0,10,0,0,0,0
0,10,18,0,17,10,0,0,0,0
0,10,0,0,0,10,0,0,0,0
19,19,19,19,19,19,19,0,0,0
0,0,0,0,0,0,0,0,0,0
0,0,0,0,0,0,0,0,0,0
0,0,0,0,0,0,0,0,0,0
0,0,0,0,0,0,0,0,0,0
endlayer

layer
0,0,0,0,0,0,0,0,0,0
0,0,0,0,0,0,0,0,0,0
16,16,16,16,16,16,16,0,0,0
0,10,0,0,0,10,0,0,0,0
19,19,19,19,19,19,19,0,0,0
0,0,0,0,0,0,0,0,0,0
0,0,0,0,0,0,0,0,0,0
0,0,0,0,0,0,0,0,0,0
0,0,0,0,0,0,0,0,0,0
0,0,0,0,0,0,0,0,0,0
endlayer

layer
0,0,0,0,0,0,0,0,0,0
0,0,0,0,0,0,0,0,0,0
0,0,0,0,0,0,0,0,0,0
20,20,20,20,20,20,20,0,0,0
0,0,0,0,0,0,0,0,0,0
0,0,0,0,0,0,0,0,0,0
0,0,0,0,0,0,0,0,0,0
0,0,0,0,0,0,0,0,0,0
0,0,0,0,0,0,0,0,0,0
0,0,0,0,0,0,0,0,0,0
endlayer

