
# Created by Ruins mod version 13.6 Ingame Parser
# authoring Player: ToonCop

unique=1
weight=1
embed_into_distance=1
unacceptable_target_blocks=flowing_water,water,flowing_lava,lava
dimensions=5,9,9
allowable_overhang=0
max_leveling=2
leveling_buffer=0
preserve_water=0
preserve_lava=0

rule1=0,100,minecraft:dirt-0
rule2=0,100,Natura:planks-4
rule3=0,100,minecraft:obsidian-0
rule4=0,100,minecraft:end_stone-0
rule5=0,100,Natura:Natura.bookshelf-4
rule6=0,5,minecraft:cauldron-0
rule7=0,100,minecraft:bed-10
rule8=0,100,minecraft:bed-2
rule9=1,100,minecraft:iron_door-3
rule10=0,100,ChestGenHook:dungeonChest:5-3
rule11=0,5,EnderStorage:enderChest-0
rule12=0,100,chisel:chisel.fenceIron-2
rule13=0,100,minecraft:iron_door-8
rule14=0,5,ExtraUtilities:chandelier-0
rule15=0,100,HardcoreEnderExpansion:obsidian_stairs-0
rule16=0,100,HardcoreEnderExpansion:obsidian_stairs-2
rule17=0,100,HardcoreEnderExpansion:obsidian_stairs-3
rule18=0,100,HardcoreEnderExpansion:obsidian_stairs-1
rule19=0,25,ChestGenHook:dungeonChest:5-3
rule20=0,100,minecraft:grass-0

layer
20,20,20,20,20,20,20,20,20
20,1,1,1,1,1,1,1,20
20,1,2,2,2,2,2,1,20
20,1,2,2,2,2,2,1,20
20,2,2,2,2,2,2,1,20
20,1,2,2,2,2,2,1,20
20,1,2,2,2,2,2,1,20
20,1,1,1,1,1,1,1,20
20,20,20,20,20,20,20,20,20
endlayer

layer
0,0,0,0,0,0,0,0,0
0,3,4,4,4,4,4,3,0
0,4,6,0,0,0,5,4,0
0,4,0,0,0,0,0,4,0
0,9,0,0,0,8,7,4,0
0,4,0,0,0,0,10,4,0
0,4,11,0,0,0,19,4,0
0,3,4,4,4,4,4,3,0
0,0,0,0,0,0,0,0,0
endlayer

layer
0,0,0,0,0,0,0,0,0
0,3,4,4,12,4,4,3,0
0,4,0,0,0,0,0,4,0
0,4,0,0,0,0,0,4,0
0,13,0,0,0,0,0,12,0
0,4,0,0,0,0,0,4,0
0,4,0,0,0,0,0,4,0
0,3,4,4,12,4,4,3,0
0,0,0,0,0,0,0,0,0
endlayer

layer
0,0,0,0,0,0,0,0,0
0,3,4,4,4,4,4,3,0
0,4,0,0,0,0,0,4,0
0,4,0,0,0,0,0,4,0
0,4,0,0,14,0,0,4,0
0,4,0,0,0,0,0,4,0
0,4,0,0,0,0,0,4,0
0,3,4,4,4,4,4,3,0
0,0,0,0,0,0,0,0,0
endlayer

layer
15,15,15,15,15,15,15,15,15
17,4,4,4,4,4,4,4,16
17,4,4,4,4,4,4,4,16
17,4,4,4,4,4,4,4,16
17,4,4,4,4,4,4,4,16
17,4,4,4,4,4,4,4,16
17,4,4,4,4,4,4,4,16
17,4,4,4,4,4,4,4,16
17,18,18,18,18,18,18,18,18
endlayer

